Workbook
Name cost_summary: Cost!$A$1:$N$35
Name Untitled: 'MMLU Pro'!$A$1:$T$36

Sheet Final wMMLUPro-v21
A1: Model | B1: Type | C1: Avg Total Test Score (w MMLU Pro) | D1: Avg CTI Test Score | E1: Avg CTI Benchmark Score | F1: Result Cost | G1: AthenaBench | W1: CyberSOCEval | AB1: CyberMetric | AE1: MMLU-Pro (accuracy)
G2: CKT (Accuracy) | H2: ATE (Accuracy) | I2: RCM (Accuracy) | J2: RMS (F1-score) | M2: VSP (Accuracy) | N2: Threat Actor Attribution (Accuracy) | U2: AB Avg I (Acc) | V2: AB Avg II (Comb) | W2: CyberSOCEval (Accuracy) | AB2: 2000 (acc) | AC2: 10000 (acc) | AD2: Avg | AE2: Summary Score (acc) | AF2: bio | AG2: bus | AH2: chem | AI2: comp sci | AJ2: econ | AK2: eng | AL2: hlth | AM2: hist | AN2: law | AO2: math | AP2: other | AQ2: phil | AR2: phys | AS2: psych | AT2: Count | AU2: Overall Score (micro avg)
G3: CKT: CTI Knowledge Test (MCQ) | H3: ATE: Attack Technique Enumeration | I3: RCM: Root Cause Mapping | J3: RMS: Risk Mitigation Strategy | M3: VSP: Vulnerability Severity Prediction | N3: TAA Classic | Q3: TAA Canonical | T3: Avg (combined) | W3: Malware | Y3: Threat Intel | AA3: Combined (acc)
J4: f1 | K4: plausible_f1 | L4: combined_f1 | N4: accurate | O4: plausible | P4: combined | Q4: accurate | R4: plausible | S4: combined | W4: acc | X4: avg | Y4: acc | Z4: avg
A5: gpt-5.5 | B5: FRONTIER | C5: =AVERAGE(AE5,G5,H5,I5,L5,M5,T5,AA5,AD5) -> 76.859444 | D5: =AVERAGE(G5,H5,I5,J5,M5,T5,W5,Y5,AB5,AC5) -> 73.485 | E5: =AVERAGE(AA5,V5,AD5) -> 72.863333 | F5: =_xlfn.XLOOKUP(A5,Cost!A:A,Cost!N:N,0) -> 508.1321 | G5: 93.66 | H5: 89 | I5: 74.6 | J5: 53.9 | K5: 56.16 | L5: 55.23 | M5: 88.73 | N5: 57 | O5: 78 | P5: 67.5 | Q5: 51.13 | R5: 56.39 | S5: 53.76 | T5: =AVERAGE(P5,S5) -> 60.63 | U5: =AVERAGE(G5,H5,I5,J5,M5,T5) -> 76.753333 | V5: =AVERAGE(T5,M5,L5,I5,H5,G5) -> 76.975 | W5: 29.3 | X5: 57.2 | Y5: 58.4 | Z5: 73.4 | AA5: =AVERAGE(W5:Y5) -> 48.3 | AB5: 95.5 | AC5: 91.13 | AD5: =AVERAGE(AB5,AC5) -> 93.315 | AE5: 88.27 | AF5: 94 | AG5: 92.3 | AH5: 90.7 | AI5: 89 | AJ5: 90.2 | AK5: 84.7 | AL5: 84.1 | AM5: 80.3 | AN5: 78.7 | AO5: 95 | AP5: 84.4 | AQ5: 86.6 | AR5: 91.3 | AS5: 88 | AT5: 12032 | AU5: 88.3
A6: gemini-3-flash-preview | B6: FRONTIER | C6: =AVERAGE(AE6,G6,H6,I6,L6,M6,T6,AA6,AD6) -> 71.668519 | D6: =AVERAGE(G6,H6,I6,J6,M6,T6,W6,Y6,AB6,AC6) -> 68.42 | E6: =AVERAGE(AA6,V6,AD6) -> 69.816667 | F6: =_xlfn.XLOOKUP(A6,Cost!A:A,Cost!N:N,0) -> 1154.1323 | G6: 91.5 | H6: 83.2 | I6: 74.5 | J6: 33.9 | K6: 35.7 | L6: 34.9 | M6: 89 | N6: 37 | O6: 86 | P6: 61.5 | Q6: 21.1 | R6: 26.3 | S6: 23.7 | T6: =AVERAGE(P6,S6) -> 42.6 | U6: =AVERAGE(G6,H6,I6,J6,M6,T6) -> 69.116667 | V6: =AVERAGE(T6,M6,L6,I6,H6,G6) -> 69.283333 | W6: 29 | X6: 58.9 | Y6: 56.3 | Z6: 71.8 | AA6: =AVERAGE(W6:Y6) -> 48.066667 | AB6: 93.9 | AC6: 90.3 | AD6: =AVERAGE(AB6,AC6) -> 92.1 | AE6: 89.15 | AF6: 94.7 | AG6: 92.3 | AH6: 92.5 | AI6: 88.3 | AJ6: 91.6 | AK6: 88.1 | AL6: 82.5 | AM6: 80.6 | AN6: 78.6 | AO6: 96.2 | AP6: 86 | AQ6: 86.2 | AR6: 92.5 | AS6: 89.1 | AT6: 12032 | AU6: 89.2
A7: deepseek-ai/DeepSeek-V4-Pro | B7: PT-OS | C7: =AVERAGE(AE7,G7,H7,I7,L7,M7,T7,AA7,AD7) -> 69.61037 | D7: =AVERAGE(G7,H7,I7,J7,M7,T7,W7,Y7,AB7,AC7) -> 67.89 | E7: =AVERAGE(AA7,V7,AD7) -> 70.422222 | F7: =_xlfn.XLOOKUP(A7,Cost!A:A,Cost!N:N,0) -> 126.3979 | G7: 88.8 | H7: 74.8 | I7: 74.1 | J7: 33.8 | K7: 36.6 | L7: 35.4 | M7: 83.5 | N7: 36 | O7: 77 | P7: 74.8 | Q7: 17.3 | R7: 20.3 | S7: 18.8 | T7: =AVERAGE(P7,S7) -> 46.8 | U7: =AVERAGE(G7,H7,I7,J7,M7,T7) -> 66.966667 | V7: =AVERAGE(T7,M7,L7,I7,H7,G7) -> 67.233333 | W7: 34.6 | X7: 63.2 | Y7: 58.9 | Z7: 73.8 | AA7: =AVERAGE(W7:Y7) -> 52.233333 | AB7: 94.2 | AC7: 89.4 | AD7: =AVERAGE(AB7,AC7) -> 91.8 | AE7: 79.06 | AF7: 89.5 | AG7: 83.8 | AH7: 77.8 | AI7: 82.9 | AJ7: 85.4 | AK7: 56.3 | AL7: 78.2 | AM7: 73.8 | AN7: 64.7 | AO7: 87.7 | AP7: 80.8 | AQ7: 82 | AR7: 81.6 | AS7: 86.2 | AT7: 12032 | AU7: 79.1
A8: gpt-5.2(reasoning=default[medium]) | B8: FRONTIER | C8: =AVERAGE(AE8,G8,H8,I8,L8,M8,T8,AA8,AD8) -> 66.973333 | D8: =AVERAGE(G8,H8,I8,J8,M8,T8,W8,Y8,AB8,AC8) -> 65.029 | E8: =AVERAGE(AA8,V8,AD8) -> 67.475556 | F8: =_xlfn.XLOOKUP(A8,Cost!A:A,Cost!N:N,0) -> 209.6696 | G8: 88.63 | H8: 61.4 | I8: 70.7 | J8: 33.67 | K8: 35.09 | L8: 34.51 | M8: 87.09 | N8: 36 | O8: 83 | P8: 59.5 | Q8: 19.55 | R8: 23.3 | S8: 21.4 | T8: =AVERAGE(P8,S8) -> 40.45 | U8: =AVERAGE(G8,H8,I8,J8,M8,T8) -> 63.656667 | V8: =AVERAGE(T8,M8,L8,I8,H8,G8) -> 63.796667 | W8: 27.68 | X8: 55.69 | Y8: 56.97 | Z8: 72.01 | AA8: =AVERAGE(W8:Y8) -> 46.78 | AB8: 94.05 | AC8: 89.65 | AD8: =AVERAGE(AB8,AC8) -> 91.85 | AE8: 81.35 | AF8: 91.1 | AG8: 82.9 | AH8: 84.6 | AI8: 83.7 | AJ8: 85 | AK8: 67.4 | AL8: 78.5 | AM8: 72.7 | AN8: 68.8 | AO8: 91.1 | AP8: 78.8 | AQ8: 80.4 | AR8: 83.8 | AS8: 85.7 | AT8: 12032 | AU8: 81.3
A9: deepseek-ai/DeepSeek-v3.2-Exp | B9: PT-OS | C9: =AVERAGE(AE9,G9,H9,I9,L9,M9,T9,AA9,AD9) -> 63.921111 | D9: =AVERAGE(G9,H9,I9,J9,M9,T9,W9,Y9,AB9,AC9) -> 62.17 | E9: =AVERAGE(AA9,V9,AD9) -> 65.961111 | F9: =_xlfn.XLOOKUP(A9,Cost!A:A,Cost!N:N,0) -> 11.2394 | G9: 86.6 | H9: 56.4 | I9: 70.4 | J9: 22.7 | K9: 22.7 | L9: 22.7 | M9: 83.7 | N9: 31 | O9: 88 | P9: 59.5 | Q9: 7.5 | R9: 9.8 | S9: 8.7 | T9: =AVERAGE(P9,S9) -> 34.1 | U9: =AVERAGE(G9,H9,I9,J9,M9,T9) -> 58.983333 | V9: =AVERAGE(T9,M9,L9,I9,H9,G9) -> 58.983333 | W9: 28.3 | X9: 57.2 | Y9: 56.1 | Z9: 73.2 | AA9: =AVERAGE(W9:Y9) -> 47.2 | AB9: 94.1 | AC9: 89.3 | AD9: =AVERAGE(AB9,AC9) -> 91.7 | AE9: 82.49 | AF9: 91.2 | AG9: 87.5 | AH9: 86.5 | AI9: 85.6 | AJ9: 87.9 | AK9: 69.2 | AL9: 80.4 | AM9: 73.8 | AN9: 67 | AO9: 90.9 | AP9: 80.5 | AQ9: 81 | AR9: 87.2 | AS9: 82.7 | AT9: 12032 | AU9: 82.6
A10: gemini-2.5-flash | B10: FRONTIER | C10: =AVERAGE(AE10,G10,H10,I10,L10,M10,T10,AA10,AD10) -> 59.761741 | D10: =AVERAGE(G10,H10,I10,J10,M10,T10,W10,Y10,AB10,AC10) -> 57.8649 | E10: =AVERAGE(AA10,V10,AD10) -> 63.436056 | F10: =_xlfn.XLOOKUP(A10,Cost!A:A,Cost!N:N,0) -> 166.2376 | G10: 79 | H10: 51.6 | I10: 65.05 | J10: 12.2 | K10: 12.7 | L10: 12.5 | M10: 78.499 | N10: 30 | O10: 87 | P10: 58.5 | Q10: 4.5 | R10: 6 | S10: 5.3 | T10: =AVERAGE(P10,S10) -> 31.9 | U10: =AVERAGE(G10,H10,I10,J10,M10,T10) -> 53.0415 | V10: =AVERAGE(T10,M10,L10,I10,H10,G10) -> 53.0915 | W10: 30.3 | X10: 60.2 | Y10: 48 | Z10: 67.1 | AA10: =AVERAGE(W10:Y10) -> 46.166667 | AB10: 93.5 | AC10: 88.6 | AD10: =AVERAGE(AB10,AC10) -> 91.05 | AE10: 82.09 | AF10: 91.2 | AG10: 87.8 | AH10: 87.9 | AI10: 85.1 | AJ10: 86 | AK10: 72.3 | AL10: 78 | AM10: 72.7 | AN10: 67.8 | AO10: 87.3 | AP10: 80 | AQ10: 78 | AR10: 86.7 | AS10: 83.2 | AT10: 12032 | AU10: 82.1
A12: asg-ai/athena-cti-sft-qwen25-32b-v21-recal-32b | B12: SFT | C12: =AVERAGE(AE12,G12,H12,I12,L12,M12,T12,AA12,AD12) -> 62.827778 | D12: =AVERAGE(G12,H12,I12,J12,M12,T12,W12,Y12,AB12,AC12) -> 62.915 | E12: =AVERAGE(AA12,V12,AD12) -> 66.311111 | F12: =_xlfn.XLOOKUP(A12,Cost!A:A,Cost!N:N,0) -> 2.8333 | G12: 75.5 | H12: 65.8 | I12: 67.1 | J12: 61.1 | K12: 63.6 | L12: 62.5 | M12: 77.8 | N12: 16 | O12: 85 | P12: 50.5 | Q12: 2.3 | R12: 4.5 | S12: 3.4 | T12: =AVERAGE(P12,S12) -> 26.95 | U12: 60.55 | V12: 66.533333 | W12: 26.4 | X12: 52.5 | Y12: 48.9 | Z12: 67.3 | AA12: =AVERAGE(W12:Y12) -> 42.6 | AB12: 92.2 | AC12: 87.4 | AD12: 89.8 | AE12: 57.4 | AF12: 78.2 | AG12: 56.5 | AH12: 47.7 | AI12: 63.2 | AJ12: 72 | AK12: 48 | AL12: 66.9 | AM12: 55.1 | AN12: 35.6 | AO12: 60.5 | AP12: 59.1 | AQ12: 59.5 | AR12: 49.1 | AS12: 72.4 | AT12: 12032 | AU12: 57.4
A13: asg-ai/athena-cti-sft-qwen25-32b-v21-cse | B13: SFT | C13: =AVERAGE(AE13,G13,H13,I13,L13,M13,T13,AA13,AD13) -> 62.185926 | D13: =AVERAGE(G13,H13,I13,J13,M13,T13,W13,Y13,AB13,AC13) -> 62.355 | E13: =AVERAGE(AA13,V13,AD13) -> 65.816667 | F13: =_xlfn.XLOOKUP(A13,Cost!A:A,Cost!N:N,0) -> 2.175 | G13: 72.5 | H13: 63.4 | I13: 67.7 | J13: 62.4 | K13: 64.7 | L13: 63.7 | M13: 78.9 | N13: 18 | O13: 89 | P13: 53.5 | Q13: 3 | R13: 3.8 | S13: 3.4 | T13: =AVERAGE(P13,S13) -> 28.45 | U13: 60.483333 | V13: 66.616667 | W13: 28.1 | X13: 53.5 | Y13: 44.5 | Z13: 64.3 | AA13: =AVERAGE(W13:Y13) -> 42.033333 | AB13: 91 | AC13: 86.6 | AD13: 88.8 | AE13: 54.19 | AF13: 77.4 | AG13: 49 | AH13: 39.2 | AI13: 61.7 | AJ13: 69.3 | AK13: 40.4 | AL13: 64.5 | AM13: 54.1 | AN13: 41 | AO13: 53.9 | AP13: 56.2 | AQ13: 57.5 | AR13: 46 | AS13: 73.8 | AT13: 12032 | AU13: 54.2
A14: asg-ai/athena-cti-sft-qwen25-32b-v21-recalibrate | B14: SFT | C14: =AVERAGE(AE14,G14,H14,I14,L14,M14,T14,AA14,AD14) -> 62.16037 | D14: =AVERAGE(G14,H14,I14,J14,M14,T14,W14,Y14,AB14,AC14) -> 62.4 | E14: =AVERAGE(AA14,V14,AD14) -> 65.858333 | F14: =_xlfn.XLOOKUP(A14,Cost!A:A,Cost!N:N,0) -> 2.5083 | G14: 76 | H14: 61.6 | I14: 68.25 | J14: 61.9 | K14: 64.8 | L14: 63.6 | M14: 75.7 | N14: 17 | O14: 84 | P14: 50.5 | Q14: 3.8 | R14: 7.5 | S14: 5.6 | T14: =AVERAGE(P14,S14) -> 28.05 | U14: 60.075 | V14: 65.941667 | W14: 27 | X14: 53.2 | Y14: 47.1 | Z14: 66.6 | AA14: =AVERAGE(W14:Y14) -> 42.433333 | AB14: 91.5 | AC14: 86.9 | AD14: 89.2 | AE14: 54.61 | AF14: 77.1 | AG14: 48.8 | AH14: 40.1 | AI14: 62.2 | AJ14: 71 | AK14: 41.3 | AL14: 66.4 | AM14: 54.3 | AN14: 40.4 | AO14: 54.8 | AP14: 55.5 | AQ14: 60.3 | AR14: 45.8 | AS14: 72.7 | AT14: 12032 | AU14: 54.6
A15: asg-ai/athena-cti-sft-qwen25-32b-v21-core | B15: SFT | C15: =AVERAGE(AE15,G15,H15,I15,L15,M15,T15,AA15,AD15) -> 63.235185 | D15: =AVERAGE(G15,H15,I15,J15,M15,T15,W15,Y15,AB15,AC15) -> 61.595 | E15: =AVERAGE(AA15,V15,AD15) -> 62.627778 | F15: =_xlfn.XLOOKUP(A15,Cost!A:A,Cost!N:N,0) -> 2.8833 | G15: 72.9 | H15: 67.2 | I15: 69.8 | J15: 62.4 | K15: 64.8 | L15: 63.8 | M15: 83.1 | N15: 11 | O15: 82 | P15: 46.5 | Q15: 6.8 | R15: 30.1 | S15: 18.4 | T15: =AVERAGE(P15,S15) -> 32.45 | U15: 61.066667 | V15: 67.216667 | W15: 7.8 | X15: 44.3 | Y15: 41.1 | Z15: 63.1 | AA15: =AVERAGE(W15:Y15) -> 31.066667 | AB15: 92 | AC15: 87.2 | AD15: 89.6 | AE15: 59.2 | AF15: 79.1 | AG15: 60.5 | AH15: 52.4 | AI15: 63.4 | AJ15: 72.3 | AK15: 50.3 | AL15: 63.8 | AM15: 54.6 | AN15: 37.8 | AO15: 63.1 | AP15: 59.1 | AQ15: 59.3 | AR15: 55 | AS15: 71.9 | AT15: 12032 | AU15: 59.2
A16: asg-ai/athena-cti-sft-qwen25-32b-v21-taa | B16: SFT | C16: =AVERAGE(AE16,G16,H16,I16,L16,M16,T16,AA16,AD16) -> 63.717778 | D16: =AVERAGE(G16,H16,I16,J16,M16,T16,W16,Y16,AB16,AC16) -> 61.72 | E16: =AVERAGE(AA16,V16,AD16) -> 62.022222 | F16: =_xlfn.XLOOKUP(A16,Cost!A:A,Cost!N:N,0) -> 2.7278 | G16: 75.4 | H16: 63.4 | I16: 69 | J16: 60.2 | K16: 64.8 | L16: 62.9 | M16: 83.5 | N16: 13 | O16: 81 | P16: 47 | Q16: 12.8 | R16: 60.9 | S16: 36.8 | T16: =AVERAGE(P16,S16) -> 41.9 | U16: 60.75 | V16: 66.866667 | W16: 8.4 | X16: 44.4 | Y16: 36.6 | Z16: 60.9 | AA16: =AVERAGE(W16:Y16) -> 29.8 | AB16: 91.9 | AC16: 86.9 | AD16: 89.4 | AE16: 58.16 | AF16: 79.9 | AG16: 59.7 | AH16: 50.8 | AI16: 64.9 | AJ16: 71.7 | AK16: 50.3 | AL16: 63.9 | AM16: 54.6 | AN16: 35.3 | AO16: 60.9 | AP16: 58.5 | AQ16: 58.1 | AR16: 52.3 | AS16: 71.2 | AT16: 12032 | AU16: 58.2
A17: Qwen/Qwen2.5-32B-Instruct | B17: INSTRUCT | C17: =AVERAGE(AE17,G17,H17,I17,L17,M17,T17,AA17,AD17) -> 49.305556 | D17: =AVERAGE(G17,H17,I17,J17,M17,T17,W17,Y17,AB17,AC17) -> 49.61 | E17: =AVERAGE(AA17,V17,AD17) -> 58.972222 | F17: =_xlfn.XLOOKUP(A17,Cost!A:A,Cost!N:N,0) -> 10.6667 | G17: 52.9 | H17: 18.2 | I17: 59.5 | J17: 7.4 | K17: 7.7 | L17: 7.6 | M17: 78.8 | N17: 16 | O17: 80 | P17: 48 | Q17: 1 | R17: 3 | S17: 2 | T17: =AVERAGE(P17,S17) -> 25 | U17: =AVERAGE(G17,H17,I17,J17,M17,N17) -> 38.8 | V17: =AVERAGE(P17,M17,L17,I17,H17,G17) -> 44.166667 | W17: 24.1 | X17: 53.8 | Y17: 49.9 | Z17: 69.1 | AA17: =AVERAGE(W17:Y17) -> 42.6 | AB17: 92.6 | AC17: 87.7 | AD17: =AVERAGE(AB17,AC17) -> 90.15 | AE17: 69 | AF17: 84.4 | AG17: 75.2 | AH17: 70.4 | AI17: 73.9 | AJ17: 77.5 | AK17: 55.2 | AL17: 70.9 | AM17: 58.3 | AN17: 44.3 | AO17: 79.1 | AP17: 66.1 | AQ17: 59.9 | AR17: 72.3 | AS17: 76.3 | AT17: 12032 | AU17: 69
A19: asg-ai/athena-cti-sft-qwen3-30b-a3b-thinking-2507-v21-cse | B19: SFT | C19: =AVERAGE(AE19,G19,H19,I19,L19,M19,T19,AA19,AD19) -> 60.595926 | D19: 60.885 | E19: 63.391667 | F19: =_xlfn.XLOOKUP(A19,Cost!A:A,Cost!N:N,0) -> 6.0694 | G19: 74.5 | H19: 58.6 | I19: 68.5 | J19: 48.7 | K19: 51 | L19: 50.1 | M19: 85 | N19: 14 | O19: 80 | P19: 47 | Q19: 2.3 | R19: 7.5 | S19: 4.9 | T19: 25.95 | U19: 60.208333 | V19: 60.441667 | W19: 22.5 | X19: 53 | Y19: 47.9 | Z19: 68.1 | AA19: =AVERAGE(W19:Y19) -> 41.133333 | AB19: 91 | AC19: 86.2 | AD19: 88.6 | AE19: 52.98 | AF19: 80.6 | AG19: 43.2 | AH19: 40.5 | AI19: 55.4 | AJ19: 69.3 | AK19: 47.5 | AL19: 63.8 | AM19: 61.7 | AN19: 36.6 | AO19: 49.5 | AP19: 52.3 | AQ19: 53.5 | AR19: 44.6 | AS19: 70.9 | AT19: 12032 | AU19: 53
A20: asg-ai/athena-cti-sft-qwen3-30b-a3b-thinking-2507-v21-recalibrate | B20: SFT | C20: =AVERAGE(AE20,G20,H20,I20,L20,M20,T20,AA20,AD20) -> 59.088148 | D20: 59 | E20: 62.316667 | F20: =_xlfn.XLOOKUP(A20,Cost!A:A,Cost!N:N,0) -> 4.4806 | G20: 63.3 | H20: 52.8 | I20: 63 | J20: 48.9 | K20: 52.4 | L20: 50.9 | M20: 83.6 | N20: 16 | O20: 82 | P20: 49 | Q20: 6 | R20: 19.6 | S20: 12.8 | T20: 30.9 | U20: 57.083333 | V20: 57.416667 | W20: 21.5 | X20: 52.3 | Y20: 48.4 | Z20: 68.5 | AA20: =AVERAGE(W20:Y20) -> 40.733333 | AB20: 91.2 | AC20: 86.4 | AD20: 88.8 | AE20: 57.76 | AF20: 80.5 | AG20: 59.8 | AH20: 54.3 | AI20: 59.3 | AJ20: 69.8 | AK20: 47.9 | AL20: 63.7 | AM20: 53.8 | AN20: 33.3 | AO20: 62.8 | AP20: 56 | AQ20: 52.1 | AR20: 56 | AS20: 68.2 | AT20: 12032 | AU20: 57.8
A21: asg-ai/athena-cti-sft-qwen3-30b-a3b-thinking-2507-v21-core | B21: SFT | C21: =AVERAGE(AE21,G21,H21,I21,L21,M21,T21,AA21,AD21) -> 59.962148 | D21: 58.875 | E21: 60.630556 | F21: =_xlfn.XLOOKUP(A21,Cost!A:A,Cost!N:N,0) -> 5.6167 | G21: 67.4 | H21: 54.4 | I21: 68.9 | J21: 53.7 | K21: 56.2 | L21: 55.2 | M21: 81.4 | N21: 21 | O21: 80 | P21: 50.5 | Q21: 6.8 | R21: 17.3 | S21: 12 | T21: 31.25 | U21: 59.508333 | V21: 59.758333 | W21: 10.5 | X21: 45.3 | Y21: 42.4 | Z21: 64.1 | AA21: =AVERAGE(W21:Y21) -> 32.733333 | AB21: 91.9 | AC21: 86.9 | AD21: 89.4 | AE21: 58.976 | AF21: 78 | AG21: 62 | AH21: 56.2 | AI21: 58.8 | AJ21: 71.3 | AK21: 53.6 | AL21: 65.3 | AM21: 54.3 | AN21: 34.7 | AO21: 64.4 | AP21: 55.8 | AQ21: 52.1 | AR21: 56.7 | AS21: 68.3 | AT21: 12032 | AU21: 59
A22: asg-ai/athena-cti-sft-qwen3-30b-a3b-thinking-2507-v21-taa | B22: SFT | C22: =AVERAGE(AE22,G22,H22,I22,L22,M22,T22,AA22,AD22) -> 59.352963 | D22: 58.37 | E22: 60.322222 | F22: =_xlfn.XLOOKUP(A22,Cost!A:A,Cost!N:N,0) -> 5.8861 | G22: 66.3 | H22: 56.4 | I22: 68.3 | J22: 48 | K22: 51.4 | L22: 50 | M22: 79.4 | N22: 15 | O22: 79 | P22: 47 | Q22: 10.5 | R22: 28.6 | S22: 19.6 | T22: 33.3 | U22: 58.616667 | V22: 58.95 | W22: 12 | X22: 45.5 | Y22: 42.9 | Z22: 64.7 | AA22: =AVERAGE(W22:Y22) -> 33.466667 | AB22: 90.9 | AC22: 86.2 | AD22: 88.55 | AE22: 58.46 | AF22: 79.1 | AG22: 63.4 | AH22: 55.9 | AI22: 56.3 | AJ22: 70 | AK22: 50.4 | AL22: 62.8 | AM22: 55.6 | AN22: 34 | AO22: 63 | AP22: 55.4 | AQ22: 51.1 | AR22: 59.7 | AS22: 66.5 | AT22: 12032 | AU22: 58.5
A23: asg-ai/athena-cti-sft-qwen3-30b-a3b-thinking-2507-v21-recal-32b | B23: SFT | C23: =AVERAGE(AE23,G23,H23,I23,L23,M23,T23,AA23,AD23) -> 59.457407 | D23: 58.105 | E23: 59.469444 | F23: =_xlfn.XLOOKUP(A23,Cost!A:A,Cost!N:N,0) -> 5.6528 | G23: 61.1 | H23: 54.8 | I23: 67.3 | J23: 48.3 | K23: 52.2 | L23: 50.6 | M23: 84.2 | N23: 12 | O23: 79 | P23: 45.5 | Q23: 14.3 | R23: 54.1 | S23: 34.2 | T23: 39.85 | U23: 59.258333 | V23: 59.641667 | W23: 20.2 | X23: 51.6 | Y23: 46.9 | Z23: 67.2 | AA23: =AVERAGE(W23:Y23) -> 39.566667 | AB23: 81.4 | AC23: 77 | AD23: 79.2 | AE23: 58.5 | AF23: 76 | AG23: 65 | AH23: 57.2 | AI23: 58.3 | AJ23: 69 | AK23: 48.7 | AL23: 63.8 | AM23: 51.4 | AN23: 33.2 | AO23: 64.6 | AP23: 57.3 | AQ23: 53.5 | AR23: 58.7 | AS23: 66 | AT23: 12032 | AU23: 58.5
A24: Qwen/Qwen3-30B-A3B-Thinking-2507 | B24: INSTRUCT | C24: =AVERAGE(AE24,G24,H24,I24,L24,M24,T24,AA24,AD24) -> 55.423333 | D24: =AVERAGE(G24,H24,I24,J24,M24,T24,W24,Y24,AB24,AC24) -> 54.928 | E24: =AVERAGE(AA24,V24,AD24) -> 61.804444 | F24: =_xlfn.XLOOKUP(A24,Cost!A:A,Cost!N:N,0) -> 192.5611 | G24: 78.7 | H24: 27.2 | I24: 61.1 | J24: 5.2 | K24: 5.4 | L24: 5.3 | M24: 81.18 | N24: 21 | O24: 94 | P24: 57.5 | Q24: 0.8 | R24: 2.3 | S24: 1.5 | T24: =AVERAGE(P24,S24) -> 29.5 | U24: =AVERAGE(G24,H24,I24,J24,M24,T24) -> 47.146667 | V24: =AVERAGE(T24,M24,L24,I24,H24,G24) -> 47.163333 | W24: 31.6 | X24: 58.2 | Y24: 54.5 | Z24: 70.8 | AA24: =AVERAGE(W24:Y24) -> 48.1 | AB24: 92.5 | AC24: 87.8 | AD24: =AVERAGE(AB24,AC24) -> 90.15 | AE24: 77.58 | AF24: 88.3 | AG24: 82 | AH24: 82.8 | AI24: 83.7 | AJ24: 84.7 | AK24: 58.7 | AL24: 75.8 | AM24: 65.6 | AN24: 56.1 | AO24: 90.9 | AP24: 74.8 | AQ24: 71.9 | AR24: 84.4 | AS24: 78.7 | AT24: 12032 | AU24: 77.6
A26: asg-ai/athena-cti-sft-qwen25-14b-v21-taa | B26: SFT | C26: =AVERAGE(AE26,G26,H26,I26,L26,M26,T26,AA26,AD26) -> 61.961111 | D26: =AVERAGE(G26,H26,I26,J26,M26,T26,W26,Y26,AB26,AC26) -> 60.8 | E26: =AVERAGE(AA26,V26,AD26) -> 61.027778 | F26: =_xlfn.XLOOKUP(A26,Cost!A:A,Cost!N:N,0) -> 3.1417 | G26: 71.6 | H26: 62 | I26: 68.3 | J26: 59.1 | K26: 62.1 | L26: 60.8 | M26: 80.7 | N26: 12 | O26: 87 | P26: 49.5 | Q26: 15 | R26: 68.4 | S26: 41.7 | T26: =AVERAGE(P26,S26) -> 45.6 | U26: 58.95 | V26: 65.483333 | W26: 10.5 | X26: 44.5 | Y26: 35 | Z26: 60.2 | AA26: =AVERAGE(W26:Y26) -> 30 | AB26: 89.8 | AC26: 85.4 | AD26: 87.6 | AE26: 51.05 | AF26: 71.4 | AG26: 56.1 | AH26: 44.8 | AI26: 52.9 | AJ26: 62.3 | AK26: 40.6 | AL26: 53.7 | AM26: 47 | AN26: 28.9 | AO26: 57.2 | AP26: 53.2 | AQ26: 47.9 | AR26: 46.1 | AS26: 63.3 | AT26: 12032 | AU26: 51
A27: asg-ai/athena-cti-sft-qwen25-14b-v21-recalibrate | B27: SFT | C27: =AVERAGE(AE27,G27,H27,I27,L27,M27,T27,AA27,AD27) -> 59.811111 | D27: =AVERAGE(G27,H27,I27,J27,M27,T27,W27,Y27,AB27,AC27) -> 59.63 | E27: =AVERAGE(AA27,V27,AD27) -> 62.3 | F27: =_xlfn.XLOOKUP(A27,Cost!A:A,Cost!N:N,0) -> 2.2472 | G27: 70.4 | H27: 61 | I27: 66.9 | J27: 56.4 | K27: 59.2 | L27: 58 | M27: 83.1 | N27: 14 | O27: 86 | P27: 50 | Q27: 2.3 | R27: 4.5 | S27: 3.4 | T27: =AVERAGE(P27,S27) -> 26.7 | U27: 58.633333 | V27: 64.9 | W27: 23.5 | X27: 47.8 | Y27: 35.5 | Z27: 59.4 | AA27: =AVERAGE(W27:Y27) -> 35.6 | AB27: 88.8 | AC27: 84 | AD27: 86.4 | AE27: 50.2 | AF27: 70.3 | AG27: 55.6 | AH27: 43.1 | AI27: 56.8 | AJ27: 63 | AK27: 36.2 | AL27: 55.5 | AM27: 47.5 | AN27: 27.3 | AO27: 54.9 | AP27: 51.7 | AQ27: 47.9 | AR27: 43.8 | AS27: 65.9 | AT27: 12032 | AU27: 50.2
A28: asg-ai/athena-cti-sft-qwen25-14b-v21-core | B28: SFT | C28: =AVERAGE(AE28,G28,H28,I28,L28,M28,T28,AA28,AD28) -> 59.991852 | D28: =AVERAGE(G28,H28,I28,J28,M28,T28,W28,Y28,AB28,AC28) -> 59.1 | E28: =AVERAGE(AA28,V28,AD28) -> 60.8 | F28: =_xlfn.XLOOKUP(A28,Cost!A:A,Cost!N:N,0) -> 3.025 | G28: 69.1 | H28: 60.8 | I28: 68.2 | J28: 59.2 | K28: 62.5 | L28: 61.1 | M28: 82.5 | N28: 13 | O28: 69 | P28: 41 | Q28: 5.3 | R28: 27.1 | S28: 16.2 | T28: =AVERAGE(P28,S28) -> 28.6 | U28: 58.8 | V28: 63.783333 | W28: 9.6 | X28: 44.7 | Y28: 35.9 | Z28: 60.7 | AA28: =AVERAGE(W28:Y28) -> 30.066667 | AB28: 90.9 | AC28: 86.2 | AD28: 88.55 | AE28: 51.01 | AF28: 72 | AG28: 54.1 | AH28: 43 | AI28: 56.6 | AJ28: 64.1 | AK28: 40.2 | AL28: 54.2 | AM28: 46.2 | AN28: 27.5 | AO28: 56.9 | AP28: 53.6 | AQ28: 48.5 | AR28: 46.6 | AS28: 64 | AT28: 12032 | AU28: 51
A29: asg-ai/athena-cti-sft-qwen25-14b-v21-cse | B29: SFT | C29: =AVERAGE(AE29,G29,H29,I29,L29,M29,T29,AA29,AD29) -> 60.164815 | D29: =AVERAGE(G29,H29,I29,J29,M29,T29,W29,Y29,AB29,AC29) -> 59.735 | E29: =AVERAGE(AA29,V29,AD29) -> 60.255556 | F29: =_xlfn.XLOOKUP(A29,Cost!A:A,Cost!N:N,0) -> 0 | G29: 70.6 | H29: 58.2 | I29: 67.3 | J29: 58.8 | K29: 60.8 | L29: 60 | M29: 72.9 | N29: 16 | O29: 81 | P29: 48.5 | Q29: 15 | R29: 78.2 | S29: 46.6 | T29: =AVERAGE(P29,S29) -> 47.55 | U29: 58.8 | V29: 63.783333 | W29: 20.9 | X29: 44.1 | Y29: 31.4 | Z29: 55.9 | AA29: =AVERAGE(W29:Y29) -> 32.133333 | AB29: 87.5 | AC29: 82.2 | AD29: =AVERAGE(AB29,AC29) -> 84.85 | AE29: 47.95 | AF29: 73.22 | AG29: 48.04 | AH29: 36.57 | AI29: 53.17 | AJ29: 62.91 | AK29: 33.02 | AL29: 55.75 | AM29: 48.03 | AN29: 32.79 | AO29: 50.41 | AP29: 48.38 | AQ29: 47.9 | AR29: 39.72 | AS29: 62.53 | AT29: 12032 | AU29: 47.95
A30: Qwen/Qwen2.5-14B-Instruct | B30: INSTRUCT | C30: =AVERAGE(AE30,G30,H30,I30,L30,M30,T30,AA30,AD30) -> 45.311852 | D30: =AVERAGE(G30,H30,I30,J30,M30,T30,W30,Y30,AB30,AC30) -> 46.149 | E30: =AVERAGE(AA30,V30,AD30) -> 56.533333 | F30: =_xlfn.XLOOKUP(A30,Cost!A:A,Cost!N:N,0) -> 6.0806 | G30: 36.8 | H30: 16 | I30: 57.1 | J30: 6.2 | K30: 6.2 | L30: 6.2 | M30: 71.8 | N30: 16 | O30: 88 | P30: 52 | Q30: 0 | R30: 0.75 | S30: 0.38 | T30: =AVERAGE(P30,S30) -> 26.19 | U30: 33.983333 | V30: 39.983333 | W30: 23.3 | X30: 53 | Y30: 47.2 | Z30: 68.5 | AA30: =AVERAGE(W30:Y30) -> 41.166667 | AB30: 91 | AC30: 85.9 | AD30: 88.45 | AE30: 64.1 | AF30: 80.3 | AG30: 71.4 | AH30: 64.1 | AI30: 68 | AJ30: 74.9 | AK30: 45.2 | AL30: 64.3 | AM30: 57 | AN30: 39.1 | AO30: 75.5 | AP30: 63 | AQ30: 55.1 | AR30: 67.5 | AS30: 71.9 | AT30: 12032 | AU30: 64.1
A32: asg-ai/athena-cti-sft-llama31-8b-v21-core | B32: SFT | C32: =AVERAGE(AE32,G32,H32,I32,L32,M32,T32,AA32,AD32) -> 52.682222 | D32: =AVERAGE(G32,H32,I32,J32,M32,T32,W32,Y32,AB32,AC32) -> 51.29 | E32: =AVERAGE(AA32,V32,AD32) -> 50.4 | F32: =_xlfn.XLOOKUP(A32,Cost!A:A,Cost!N:N,0) -> 1.4583 | G32: 64.9 | H32: 62.2 | I32: 65.6 | J32: 60 | K32: 62.2 | L32: 61.3 | M32: 82.1 | N32: 4 | O32: 21 | P32: 12.5 | Q32: 6.8 | R32: 29.3 | S32: 18.1 | T32: =AVERAGE(P32,S32) -> 15.3 | U32: 56.466667 | V32: 58.1 | W32: 4.6 | X32: 39.7 | Y32: 4.6 | Z32: 38.6 | AA32: =AVERAGE(W32:Y32) -> 16.3 | AB32: 78.3 | AC32: 75.3 | AD32: 76.8 | AE32: 29.64 | AF32: 54.3 | AG32: 30.4 | AH32: 18.6 | AI32: 27.6 | AJ32: 37.3 | AK32: 15.7 | AL32: 37.3 | AM32: 32.8 | AN32: 18.3 | AO32: 28.3 | AP32: 32.6 | AQ32: 32.3 | AR32: 24.5 | AS32: 44.1 | AT32: 12032 | AU32: 29.6
A33: asg-ai/athena-cti-sft-llama31-8b-v21-recalibrate | B33: SFT | C33: =AVERAGE(AE33,G33,H33,I33,L33,M33,T33,AA33,AD33) -> 51.91037 | D33: =AVERAGE(G33,H33,I33,J33,M33,T33,W33,Y33,AB33,AC33) -> 50.755 | E33: =AVERAGE(AA33,V33,AD33) -> 50.45 | F33: =_xlfn.XLOOKUP(A33,Cost!A:A,Cost!N:N,0) -> 0.8139 | G33: 59.3 | H33: 60.4 | I33: 67.7 | J33: 57.9 | K33: 60 | L33: 59.1 | M33: 75.3 | N33: 7 | O33: 69 | P33: 38 | Q33: 8.3 | R33: 21.1 | S33: 14.7 | T33: =AVERAGE(P33,S33) -> 26.35 | U33: 54.6 | V33: 59.966667 | W33: 11 | X33: 41.9 | Y33: 6.3 | Z33: 40.2 | AA33: =AVERAGE(W33:Y33) -> 19.733333 | AB33: 72.5 | AC33: 70.8 | AD33: 71.65 | AE33: 27.66 | AF33: 46.2 | AG33: 24.6 | AH33: 20.1 | AI33: 29.3 | AJ33: 34.1 | AK33: 19.2 | AL33: 36.6 | AM33: 26 | AN33: 19.8 | AO33: 23 | AP33: 28.7 | AQ33: 28.3 | AR33: 24.4 | AS33: 41.6 | AT33: 12032 | AU33: 27.7
A34: asg-ai/athena-cti-sft-llama31-8b-v21-taa | B34: SFT | C34: =AVERAGE(AE34,G34,H34,I34,L34,M34,T34,AA34,AD34) -> 51.588889 | D34: =AVERAGE(G34,H34,I34,J34,M34,T34,W34,Y34,AB34,AC34) -> 50.545 | E34: =AVERAGE(AA34,V34,AD34) -> 49.588889 | F34: =_xlfn.XLOOKUP(A34,Cost!A:A,Cost!N:N,0) -> 2.5778 | G34: 62.8 | H34: 55.6 | I34: 63.1 | J34: 56.2 | K34: 58.1 | L34: 57.3 | M34: 67.7 | N34: 6 | O34: 75 | P34: 45.5 | Q34: 15.8 | R34: 70.7 | S34: 43.2 | T34: =AVERAGE(P34,S34) -> 44.35 | U34: 51.9 | V34: 58.666667 | W34: 4.1 | X34: 40.1 | Y34: 2.6 | Z34: 37.8 | AA34: =AVERAGE(W34:Y34) -> 15.6 | AB34: 75.5 | AC34: 73.5 | AD34: 74.5 | AE34: 23.35 | AF34: 44.35 | AG34: 23.19 | AH34: 13.96 | AI34: 18.54 | AJ34: 33.53 | AK34: 16.2 | AL34: 33.13 | AM34: 24.15 | AN34: 16.62 | AO34: 15.32 | AP34: 24.35 | AQ34: 23.85 | AR34: 17.55 | AS34: 38.72 | AT34: 12032 | AU34: 23.35
A35: asg-ai/athena-cti-sft-llama31-8b-v21-cse | B35: SFT | C35: =AVERAGE(AE35,G35,H35,I35,L35,M35,T35,AA35,AD35) -> 46.678148 | D35: =AVERAGE(G35,H35,I35,J35,M35,T35,W35,Y35,AB35,AC35) -> 46.985 | E35: =AVERAGE(AA35,V35,AD35) -> 46.8 | F35: =_xlfn.XLOOKUP(A35,Cost!A:A,Cost!N:N,0) -> 0.7917 | G35: 64.4 | H35: 49.8 | I35: 65.1 | J35: 34.4 | K35: 35.8 | L35: 35.2 | M35: 71 | N35: 2 | O35: 26 | P35: 14 | Q35: 5.3 | R35: 54.1 | S35: 29.7 | T35: =AVERAGE(P35,S35) -> 21.85 | U35: 47.783333 | V35: 49.916667 | W35: 14.6 | X35: 40.7 | Y35: 13.8 | Z35: 45.3 | AA35: =AVERAGE(W35:Y35) -> 23.033333 | AB35: 68.9 | AC35: 66 | AD35: 67.45 | AE35: 22.27 | AF35: 44.8 | AG35: 15.8 | AH35: 14.6 | AI35: 23.4 | AJ35: 31.8 | AK35: 19 | AL35: 26.5 | AM35: 22.6 | AN35: 18.4 | AO35: 14.7 | AP35: 21.6 | AQ35: 21.2 | AR35: 15.2 | AS35: 39.1 | AT35: 12032 | AU35: 22.3
A36: meta-llama/Meta-Llama-3.1-8B-Instruct | B36: INSTRUCT | C36: =AVERAGE(AE36,G36,H36,I36,L36,M36,T36,AA36,AD36) -> 42.675926 | D36: =AVERAGE(G36,H36,I36,J36,M36,T36,W36,Y36,AB36,AC36) -> 43.43 | E36: =AVERAGE(AA36,V36,AD36) -> 51.622222 | F36: =_xlfn.XLOOKUP(A36,Cost!A:A,Cost!N:N,0) -> 4.275 | G36: 59.7 | H36: 12 | I36: 42.1 | J36: 7.8 | K36: 8 | L36: 7.9 | M36: 73.6 | N36: 18 | O36: 64 | P36: 41 | Q36: 3.8 | R36: 14.3 | S36: 9 | T36: =AVERAGE(P36,S36) -> 25 | U36: 35.533333 | V36: 39.383333 | W36: 16.1 | X36: 47.9 | Y36: 29.1 | Z36: 58.3 | AA36: =AVERAGE(W36:Y36) -> 31.033333 | AB36: 86.2 | AC36: 82.7 | AD36: 84.45 | AE36: 48.3 | AF36: 68.6 | AG36: 51.8 | AH36: 42.8 | AI36: 48.8 | AJ36: 57.6 | AK36: 28.2 | AL36: 58.9 | AM36: 46.2 | AN36: 31.2 | AO36: 52.3 | AP36: 50.4 | AQ36: 40.5 | AR36: 43.8 | AS36: 64.8 | AT36: 12032 | AU36: 48.3
A38: asg-ai/athena-cti-sft-foundation-8b-v21-core | B38: SFT | C38: =AVERAGE(AE38,G38,H38,I38,L38,M38,T38,AA38,AD38) -> 54.459259 | D38: =AVERAGE(G38,H38,I38,J38,M38,T38,W38,Y38,AB38,AC38) -> 53.355 | E38: =AVERAGE(AA38,V38,AD38) -> 53.088889 | F38: =_xlfn.XLOOKUP(A38,Cost!A:A,Cost!N:N,0) -> 1.9833 | G38: 62.4 | H38: 62.4 | I38: 67.1 | J38: 58.5 | K38: 60.6 | L38: 59.7 | M38: 84 | N38: 17 | O38: 55 | P38: 36 | Q38: 3.8 | R38: 32.2 | S38: 18.1 | T38: =AVERAGE(P38,S38) -> 27.05 | U38: 58.566667 | V38: 61.933333 | W38: 4.3 | X38: 40.4 | Y38: 8.8 | Z38: 40.8 | AA38: =AVERAGE(W38:Y38) -> 17.833333 | AB38: 81.1 | AC38: 77.9 | AD38: 79.5 | AE38: 30.15 | AF38: 58.2 | AG38: 30.2 | AH38: 20.7 | AI38: 31.7 | AJ38: 40.2 | AK38: 18.9 | AL38: 35.1 | AM38: 31 | AN38: 19.2 | AO38: 26 | AP38: 32.9 | AQ38: 29.1 | AR38: 22 | AS38: 48.2 | AT38: 12032 | AU38: 30.2
A39: asg-ai/athena-cti-sft-foundation-8b-v21-recalibrate | B39: SFT | C39: =AVERAGE(AE39,G39,H39,I39,L39,M39,T39,AA39,AD39) -> 52.442963 | D39: =AVERAGE(G39,H39,I39,J39,M39,T39,W39,Y39,AB39,AC39) -> 53.175 | E39: =AVERAGE(AA39,V39,AD39) -> 53.822222 | F39: =_xlfn.XLOOKUP(A39,Cost!A:A,Cost!N:N,0) -> 1.8667 | G39: 53.8 | H39: 60 | I39: 68.4 | J39: 38.8 | K39: 47.1 | L39: 43.5 | M39: 83.6 | N39: 14 | O39: 67 | P39: 40.5 | Q39: 15.8 | R39: 39.1 | S39: 27.4 | T39: =AVERAGE(P39,S39) -> 33.95 | U39: 53.1 | V39: 58.3 | W39: 16.1 | X39: 41.7 | Y39: 27.9 | Z39: 53.5 | AA39: =AVERAGE(W39:Y39) -> 28.566667 | AB39: 75.3 | AC39: 73.9 | AD39: 74.6 | AE39: 25.57 | AF39: 44.49 | AG39: 23.57 | AH39: 17.84 | AI39: 24.88 | AJ39: 31.99 | AK39: 17.65 | AL39: 28.61 | AM39: 27.56 | AN39: 18.62 | AO39: 23.54 | AP39: 28.79 | AQ39: 24.85 | AR39: 21.25 | AS39: 37.47 | AT39: 12032 | AU39: 25.57
A40: fdtn-ai/Foundation-Sec-8B-Instruct | B40: INSTRUCT | C40: =AVERAGE(AE40,G40,H40,I40,L40,M40,T40,AA40,AD40) -> 51.875556 | D40: =AVERAGE(G40,H40,I40,J40,M40,T40,W40,Y40,AB40,AC40) -> 52.735 | E40: =AVERAGE(AA40,V40,AD40) -> 57.705556 | F40: =_xlfn.XLOOKUP(A40,Cost!A:A,Cost!N:N,0) -> 3.3528 | G40: 77.8 | H40: 36.6 | I40: 65 | J40: 26.9 | K40: 28.2 | L40: 27.7 | M40: 65.3 | N40: 26 | O40: 87 | P40: 56.5 | Q40: 3.8 | R40: 15 | S40: 9.4 | T40: =AVERAGE(P40,S40) -> 32.95 | U40: 49.6 | V40: 54.816667 | W40: 16.8 | X40: 48.4 | Y40: 38.6 | Z40: 62 | AA40: =AVERAGE(W40:Y40) -> 34.6 | AB40: 85.7 | AC40: 81.7 | AD40: 83.7 | AE40: 43.23 | AF40: 64.2 | AG40: 49.2 | AH40: 35.9 | AI40: 47.3 | AJ40: 52.5 | AK40: 26.4 | AL40: 47.2 | AM40: 39.6 | AN40: 25.9 | AO40: 48.9 | AP40: 45.8 | AQ40: 37.3 | AR40: 38.2 | AS40: 58.6 | AT40: 12032 | AU40: 43.2
A41: asg-ai/athena-cti-sft-foundation-8b-v21-cse | B41: SFT | C41: =AVERAGE(AE41,G41,H41,I41,L41,M41,T41,AA41,AD41) -> 41.258148 | D41: =AVERAGE(G41,H41,I41,J41,M41,T41,W41,Y41,AB41,AC41) -> 43.885 | E41: =AVERAGE(AA41,V41,AD41) -> 48.133333 | F41: =_xlfn.XLOOKUP(A41,Cost!A:A,Cost!N:N,0) -> 2.8194 | G41: 38.5 | H41: 27.8 | I41: 45.6 | J41: 33.4 | K41: 38.4 | L41: 36.3 | M41: 87.4 | N41: 1 | O41: 20 | P41: 10.5 | Q41: 4.5 | R41: 21.1 | S41: 12.8 | T41: =AVERAGE(P41,S41) -> 11.65 | U41: 38.95 | V41: 41.016667 | W41: 18.7 | X41: 41.6 | Y41: 27.7 | Z41: 53.4 | AA41: =AVERAGE(W41:Y41) -> 29.333333 | AB41: 74.7 | AC41: 73.4 | AD41: 74.05 | AE41: 20.69 | AF41: 41.6 | AG41: 14.6 | AH41: 12.5 | AI41: 21.2 | AJ41: 31.8 | AK41: 14.9 | AL41: 24.3 | AM41: 24.1 | AN41: 17.3 | AO41: 13 | AP41: 22.8 | AQ41: 20.8 | AR41: 13.9 | AS41: 35.5 | AT41: 12032 | AU41: 20.7
A42: asg-ai/athena-cti-sft-foundation-8b-v21-taa | B42: SFT | C42: =AVERAGE(AE42,G42,H42,I42,L42,M42,T42,AA42,AD42) -> 43.116296 | D42: =AVERAGE(G42,H42,I42,J42,M42,T42,W42,Y42,AB42,AC42) -> 42.915 | E42: =AVERAGE(AA42,V42,AD42) -> 46.055556 | F42: =_xlfn.XLOOKUP(A42,Cost!A:A,Cost!N:N,0) -> 6.8889 | G42: 41.5 | H42: 23 | I42: 52.2 | J42: 50.7 | K42: 54.8 | L42: 53 | M42: 81.2 | N42: 1 | O42: 24 | P42: 12.5 | Q42: 10.5 | R42: 28.6 | S42: 19.6 | T42: =AVERAGE(P42,S42) -> 16.05 | U42: 41.6 | V42: 43.9 | W42: 5.7 | X42: 41.6 | Y42: 5.4 | Z42: 41.4 | AA42: =AVERAGE(W42:Y42) -> 17.566667 | AB42: 78 | AC42: 75.4 | AD42: 76.7 | AE42: 26.83 | AF42: 55 | AG42: 23.8 | AH42: 19.2 | AI42: 30.5 | AJ42: 37 | AK42: 19.8 | AL42: 30.6 | AM42: 31 | AN42: 19.3 | AO42: 17.8 | AP42: 27.7 | AQ42: 24 | AR42: 18.2 | AS42: 46 | AT42: 12032 | AU42: 26.8

Sheet Cost
A1: model_key | B1: model | C1: athena_cost_usd | D1: cybersoceval_cost_usd | E1: cybermetric_cost_usd | F1: mmlu_pro_cost_usd | G1: total_input_tok | H1: total_output_tok | I1: usd_per_1k_tok | J1: wallclock_hours | K1: gpu_hours_billed | L1: billing_basis | M1: reasoning_effort | N1: total_cost_usd
A2: gemini-3-flash-preview | B2: gemini-3-flash | C2: 5.7202 | D2: 78.4613 | E2: 64.4625 | F2: 1005.4883 | G2: 12049618 | H2: 382702497 | I2: 0.002924 | L2: API tokens | M2: default | N2: 1154.1323
A3: gpt-5.5 | B3: gpt5.5 | C3: 202.6194 | D3: 79.1854 | E3: 38.7299 | F3: 187.5974 | G3: 19765005 | H3: 13643569 | I3: 0.01521 | L3: API tokens | M3: medium | N3: 508.1321
A4: gpt-5.2(reasoning=default[medium]) | B4: gpt5.2 | C4: 30.4439 | D4: 23.2834 | E4: 4.0444 | F4: 151.8979 | G4: 22659871 | H4: 12143915 | I4: 0.006024 | L4: API tokens | M4: medium | N4: 209.6696
A5: Qwen/Qwen3-30B-A3B-Thinking-2507 | B5: qwen3-30b-a3b-thinking-2507-vllm | C5: 41.0528 | D5: 12.8833 | E5: 23.3722 | F5: 115.2528 | J5: 38.512 | K5: 77.024 | L5: 2xH100 @ $2.50/hr | N5: 192.5611
A6: gemini-2.5-flash | B6: gemini-2.5-flash | C6: 56.6752 | D6: 12.2585 | E6: 19.0787 | F6: 78.2252 | G6: 20977607 | H6: 63977724 | I6: 0.001957 | L6: API tokens | N6: 166.2376
A7: deepseek-ai/DeepSeek-V4-Pro | B7: deepseek-v4-pro-hf | C7: 0.3222 | D7: 27.9262 | E7: 9.8686 | F7: 88.2809 | G7: 20817369 | H7: 25912563 | I7: 0.002705 | L7: API tokens | N7: 126.3979
A8: deepseek-ai/DeepSeek-V3.1-Terminus | B8: deepseek-v3.1-terminus-hf | C8: 2.4458 | D8: 3.7016 | E8: 0.4794 | F8: 7.7003 | G8: 20321220 | H8: 8840449 | I8: 0.000491 | L8: API tokens | N8: 14.3272
A9: deepseek-ai/DeepSeek-V3.2-Exp | B9: deepseek-v3.2-exp-hf | C9: 0.0062 | D9: 3.6839 | E9: 0.4501 | F9: 7.0992 | G9: 20965383 | H9: 13946977 | I9: 0.000322 | L9: API tokens | N9: 11.2394
A10: Qwen/Qwen2.5-32B-Instruct | B10: qwen2.5-32b-vllm | C10: 2.5361 | D10: 0.6139 | E10: 0.2306 | F10: 7.2861 | J10: 2.133 | K10: 4.267 | L10: 2xH100 @ $2.50/hr | N10: 10.6667
A11: asg-ai/athena-cti-sft-foundation-8b-v21-taa | B11: athena-cti-sft-foundation-8b-v21-taa-vllm | C11: 1.2722 | D11: 1.1778 | E11: 0.725 | F11: 3.7139 | J11: 1.378 | K11: 2.756 | L11: 2xH100 @ $2.50/hr | N11: 6.8889
A12: Qwen/Qwen2.5-14B-Instruct | B12: qwen2.5-14b-vllm | C12: 1.4278 | D12: 0.3917 | E12: 0.1667 | F12: 4.0944 | J12: 1.216 | K12: 2.432 | L12: 2xH100 @ $2.50/hr | N12: 6.0806
A13: asg-ai/athena-cti-sft-qwen3-30b-a3b-thinking-2507-v21-cse | B13: asg-ai_athena-cti-sft-qwen3-30b-a3b-thinking-2507-v21-cse | C13: 4.9833 | D13: 0.3444 | E13: 0.3528 | F13: 0.3889 | J13: 1.214 | K13: 2.428 | L13: 2xH100 @ $2.50/hr | N13: 6.0694
A14: asg-ai/athena-cti-sft-qwen3-30b-a3b-thinking-2507-v21-taa | B14: athena-cti-sft-qwen3-30b-a3b-thinking-2507-v21-taa-no-think-vllm | C14: 2.9889 | D14: 0.3472 | E14: 0.5028 | F14: 2.0472 | J14: 1.177 | K14: 2.354 | L14: 2xH100 @ $2.50/hr | N14: 5.8861
A15: asg-ai/athena-cti-sft-qwen3-30b-a3b-thinking-2507-v21-recal-32b | B15: athena-cti-sft-qwen3-30b-a3b-thinking-2507-v21-recal-32b-no-think-vllm | C15: 2.1278 | D15: 0.3472 | E15: 1.2222 | F15: 1.9556 | J15: 1.131 | K15: 2.261 | L15: 2xH100 @ $2.50/hr | N15: 5.6528
A16: asg-ai/athena-cti-sft-qwen3-30b-a3b-thinking-2507-v21-core | B16: athena-cti-sft-qwen3-30b-a3b-thinking-2507-v21-core-no-think-vllm | C16: 3.175 | D16: 0.3583 | E16: 0.3389 | F16: 1.7444 | J16: 1.123 | K16: 2.247 | L16: 2xH100 @ $2.50/hr | N16: 5.6167
A17: Qwen/Qwen3-30B-A3B-Instruct-2507 | B17: qwen3-30b-a3b-instruct-2507-vllm | C17: 3.8444 | D17: 0.3389 | E17: 0.3278 | J17: 0.902 | K17: 1.804 | L17: 2xH100 @ $2.50/hr | N17: 4.5111
A18: asg-ai/athena-cti-sft-qwen3-30b-a3b-thinking-2507-v21-recalibrate | B18: athena-cti-sft-qwen3-30b-a3b-thinking-2507-v21-recalibrate-no-think-vllm | C18: 2.0861 | D18: 0.3417 | E18: 0.3333 | F18: 1.7194 | J18: 0.896 | K18: 1.792 | L18: 2xH100 @ $2.50/hr | N18: 4.4806
A19: meta-llama/Meta-Llama-3.1-8B-Instruct | B19: llama-3-8b-vllm | C19: 1.0889 | D19: 0.325 | E19: 0.1167 | F19: 2.7444 | J19: 0.855 | K19: 1.71 | L19: 2xH100 @ $2.50/hr | N19: 4.275
A20: fdtn-ai/Foundation-Sec-8B-Instruct | B20: foundation-8b-instruct-vllm | C20: 0.5306 | D20: 0.1833 | E20: 0.1167 | F20: 2.5222 | J20: 0.671 | K20: 1.341 | L20: 2xH100 @ $2.50/hr | N20: 3.3528
A21: asg-ai/athena-cti-sft-qwen25-14b-v21-taa | B21: athena-cti-sft-qwen25-14b-v21-taa-vllm | C21: 1.2889 | D21: 0.5778 | E21: 0.1972 | F21: 1.0778 | J21: 0.628 | K21: 1.257 | L21: 2xH100 @ $2.50/hr | N21: 3.1417
A22: asg-ai/athena-cti-sft-qwen25-14b-v21-core | B22: athena-cti-sft-qwen25-14b-v21-core-vllm | C22: 1.2389 | D22: 0.7111 | E22: 0.1917 | F22: 0.8833 | J22: 0.605 | K22: 1.21 | L22: 2xH100 @ $2.50/hr | N22: 3.025
A23: asg-ai/athena-cti-sft-qwen25-32b-v21-core | B23: athena-cti-sft-qwen25-32b-v21-core-vllm | C23: 1.0667 | D23: 0.65 | E23: 0.2333 | F23: 0.9333 | J23: 0.577 | K23: 1.153 | L23: 2xH100 @ $2.50/hr | N23: 2.8833
A24: asg-ai/athena-cti-sft-qwen25-32b-v21-recal-32b | B24: athena-cti-sft-qwen25-32b-v21-recal-32b-vllm | C24: 1.2194 | D24: 0.5944 | E24: 0.2333 | F24: 0.7861 | J24: 0.567 | K24: 1.133 | L24: 2xH100 @ $2.50/hr | N24: 2.8333
A25: asg-ai/athena-cti-sft-foundation-8b-v21-cse | B25: athena-cti-sft-foundation-8b-v21-cse-vllm | C25: 0.825 | D25: 0.2583 | E25: 0.4444 | F25: 1.2917 | J25: 0.564 | K25: 1.128 | L25: 2xH100 @ $2.50/hr | N25: 2.8194
A26: asg-ai/athena-cti-sft-qwen25-32b-v21-taa | B26: athena-cti-sft-qwen25-32b-v21-taa-vllm | C26: 0.9833 | D26: 0.6528 | E26: 0.2278 | F26: 0.8639 | J26: 0.546 | K26: 1.091 | L26: 2xH100 @ $2.50/hr | N26: 2.7278
A27: asg-ai/athena-cti-sft-llama31-8b-v21-taa | B27: athena-cti-sft-llama31-8b-v21-taa-vllm | C27: 0.6222 | D27: 0.8944 | E27: 0.1194 | F27: 0.9417 | J27: 0.516 | K27: 1.031 | L27: 2xH100 @ $2.50/hr | N27: 2.5778
A28: asg-ai/athena-cti-sft-qwen25-32b-v21-recalibrate | B28: athena-cti-sft-qwen25-32b-v21-recalibrate-vllm | C28: 1.0361 | D28: 0.5889 | E28: 0.2361 | F28: 0.6472 | J28: 0.502 | K28: 1.003 | L28: 2xH100 @ $2.50/hr | N28: 2.5083
A29: asg-ai/athena-cti-sft-qwen25-14b-v21-recalibrate | B29: athena-cti-sft-qwen25-14b-v21-recalibrate-vllm | C29: 0.8444 | D29: 0.5611 | E29: 0.2 | F29: 0.6417 | J29: 0.449 | K29: 0.899 | L29: 2xH100 @ $2.50/hr | N29: 2.2472
... A35: asg-ai/athena-cti-sft-llama31-8b-v21-cse | B35: athena-cti-sft-llama31-8b-v21-cse-vllm | C35: 0.2861 | D35: 0.1861 | E35: 0.1194 | F35: 0.2 | J35: 0.158 | K35: 0.317 | L35: 2xH100 @ $2.50/hr | N35: 0.7917
A38: ftdn-ai/Foundation-Sec-8B-Instruct

Sheet MMLU Pro
B1: model | C1: biolog | D1: busine | E1: chemis | F1: comput | G1: econom | H1: engine | I1: health | J1: histor | K1: law | L1: math | M1: other | N1: philos | O1: physic | P1: psycho | Q1: N | R1: overall | S1: parse%
B2: --- | C2: --- | D2: --- | E2: --- | F2: --- | G2: --- | H2: --- | I2: --- | J2: --- | K2: --- | L2: --- | M2: --- | N2: --- | O2: --- | P2: --- | Q2: --- | R2: --- | S2: ---
B3: Qwen_Qwen2.5-14B-Instruct | C3: 80.3 | D3: 71.4 | E3: 64.1 | F3: 68 | G3: 74.9 | H3: 45.2 | I3: 64.3 | J3: 57 | K3: 39.1 | L3: 75.5 | M3: 63 | N3: 55.1 | O3: 67.5 | P3: 71.9 | Q3: 12032 | R3: 64.1 | S3: 1.1
B4: Qwen_Qwen2.5-32B-Instruct | C4: 84.4 | D4: 75.2 | E4: 70.4 | F4: 73.9 | G4: 77.5 | H4: 55.2 | I4: 70.9 | J4: 58.3 | K4: 44.3 | L4: 79.1 | M4: 66.1 | N4: 59.9 | O4: 72.3 | P4: 76.2 | Q4: 12032 | R4: 69 | S4: 0.4
B5: asg-ai_athena-cti-sft-qwen3-30b-a3b-thinking-2507-v21-cse | C5: 80.6 | D5: 43.2 | E5: 40.5 | F5: 55.4 | G5: 69.3 | H5: 47.5 | I5: 63.8 | J5: 61.7 | K5: 36.6 | L5: 49.5 | M5: 52.3 | N5: 53.5 | O5: 44.6 | P5: 70.9 | Q5: 12032 | R5: 53 | S5: 0
B6: athena-cti-sft-foundation-8b-v21-core-vllm | C6: 58.2 | D6: 30.2 | E6: 20.7 | F6: 31.7 | G6: 40.2 | H6: 18.9 | I6: 35.1 | J6: 31 | K6: 19.2 | L6: 26 | M6: 32.9 | N6: 29.1 | O6: 22 | P6: 48.2 | Q6: 12032 | R6: 30.2 | S6: 0.7
B7: athena-cti-sft-foundation-8b-v21-cse-vllm | C7: 41.6 | D7: 14.6 | E7: 12.5 | F7: 21.2 | G7: 31.8 | H7: 14.9 | I7: 24.3 | J7: 24.1 | K7: 17.3 | L7: 13 | M7: 22.8 | N7: 20.8 | O7: 13.9 | P7: 35.5 | Q7: 12032 | R7: 20.7 | S7: 0.2
B8: athena-cti-sft-foundation-8b-v21-taa-vllm | C8: 55 | D8: 23.8 | E8: 19.2 | F8: 30.5 | G8: 37 | H8: 19.8 | I8: 30.6 | J8: 31 | K8: 19.3 | L8: 17.8 | M8: 27.7 | N8: 24 | O8: 18.2 | P8: 46 | Q8: 12032 | R8: 26.8 | S8: 0.6
B9: athena-cti-sft-llama31-8b-v21-core-vllm | C9: 54.3 | D9: 30.4 | E9: 18.6 | F9: 27.6 | G9: 37.3 | H9: 15.7 | I9: 37.3 | J9: 32.8 | K9: 18.3 | L9: 28.3 | M9: 32.6 | N9: 32.3 | O9: 24.5 | P9: 44.1 | Q9: 12032 | R9: 29.6 | S9: 8.4
B10: athena-cti-sft-llama31-8b-v21-cse-vllm | C10: 44.8 | D10: 15.8 | E10: 14.6 | F10: 23.4 | G10: 31.8 | H10: 19 | I10: 26.5 | J10: 22.6 | K10: 18.4 | L10: 14.7 | M10: 21.6 | N10: 21.2 | O10: 15.2 | P10: 39.1 | Q10: 12032 | R10: 22.3 | S10: 0.4
B11: athena-cti-sft-llama31-8b-v21-recalibrate-vllm | C11: 46.2 | D11: 24.6 | E11: 20.1 | F11: 29.3 | G11: 34.1 | H11: 19.2 | I11: 36.6 | J11: 26 | K11: 19.8 | L11: 23 | M11: 28.7 | N11: 28.3 | O11: 24.4 | P11: 41.6 | Q11: 12032 | R11: 27.7 | S11: 5.3
B12: athena-cti-sft-llama31-8b-v21-taa-vllm | C12: 44.4 | D12: 23.2 | E12: 14 | F12: 18.5 | G12: 33.5 | H12: 16.2 | I12: 33.1 | J12: 24.1 | K12: 16.6 | L12: 15.3 | M12: 24.4 | N12: 23.8 | O12: 17.6 | P12: 38.7 | Q12: 12032 | R12: 23.3 | S12: 19.5
B13: athena-cti-sft-qwen25-14b-v21-core-vllm | C13: 72 | D13: 54.1 | E13: 43 | F13: 56.6 | G13: 64.1 | H13: 40.2 | I13: 54.2 | J13: 46.2 | K13: 27.5 | L13: 56.9 | M13: 53.6 | N13: 48.5 | O13: 46.6 | P13: 64 | Q13: 12032 | R13: 51 | S13: 0.8
B14: athena-cti-sft-qwen25-14b-v21-recalibrate-vllm | C14: 70.3 | D14: 55.6 | E14: 43.1 | F14: 56.8 | G14: 63 | H14: 36.2 | I14: 55.5 | J14: 47.5 | K14: 27.3 | L14: 54.9 | M14: 51.7 | N14: 47.9 | O14: 43.8 | P14: 65.9 | Q14: 12032 | R14: 50.2 | S14: 0.4
... B25: athena-cti-sft-qwen3-30b-a3b-thinking-2507-v21-taa-no-think-vllm | C25: 79.1 | D25: 63.4 | E25: 55.9 | F25: 56.3 | G25: 70 | H25: 50.4 | I25: 62.8 | J25: 55.6 | K25: 34 | L25: 63 | M25: 55.4 | N25: 51.1 | O25: 59.7 | P25: 66.5 | Q25: 12032 | R25: 58.5 | S25: 1.9
B26: deepseek-v3.1-terminus-hf | C26: ‚Äî | D26: 78.3 | E26: ‚Äî | F26: ‚Äî | G26: ‚Äî | H26: ‚Äî | I26: ‚Äî | J26: ‚Äî | K26: ‚Äî | L26: ‚Äî | M26: ‚Äî | N26: ‚Äî | O26: ‚Äî | P26: ‚Äî | Q26: 23 | R26: 78.3 | S26: 0
B27: deepseek-v3.2-exp-hf | C27: 91.2 | D27: 87.5 | E27: 86.5 | F27: 85.6 | G27: 87.9 | H27: 69.2 | I27: 80.4 | J27: 73.8 | K27: 67 | L27: 90.9 | M27: 80.5 | N27: 81 | O27: 87.2 | P27: 82.7 | Q27: 12032 | R27: 82.6 | S27: 0.3
B28: deepseek-v4-pro-hf | C28: 89.5 | D28: 83.8 | E28: 77.8 | F28: 82.9 | G28: 85.4 | H28: 56.3 | I28: 78.2 | J28: 73.8 | K28: 64.7 | L28: 87.7 | M28: 80.8 | N28: 82 | O28: 81.6 | P28: 86.2 | Q28: 12032 | R28: 79.1 | S28: 0.9
B29: foundation-8b-instruct-vllm | C29: 64.2 | D29: 49.2 | E29: 35.9 | F29: 47.3 | G29: 52.5 | H29: 26.4 | I29: 47.2 | J29: 39.6 | K29: 25.9 | L29: 48.9 | M29: 45.8 | N29: 37.3 | O29: 38.2 | P29: 58.6 | Q29: 12032 | R29: 43.2 | S29: 1.1
B30: gemini-2.5-flash | C30: 91.2 | D30: 87.8 | E30: 87.9 | F30: 85.1 | G30: 86 | H30: 72.3 | I30: 78 | J30: 72.7 | K30: 67.8 | L30: 87.3 | M30: 80 | N30: 78 | O30: 86.7 | P30: 83.2 | Q30: 12032 | R30: 82.1 | S30: 0.7
B31: gemini-3-flash | C31: 94.7 | D31: 92.3 | E31: 92.5 | F31: 88.3 | G31: 91.6 | H31: 88.1 | I31: 82.5 | J31: 80.6 | K31: 78.6 | L31: 96.2 | M31: 86 | N31: 86.2 | O31: 92.5 | P31: 89.1 | Q31: 12032 | R31: 89.2 | S31: 0.1
B32: gpt5.2 | C32: 91.1 | D32: 82.9 | E32: 84.6 | F32: 83.7 | G32: 85 | H32: 67.4 | I32: 78.5 | J32: 72.7 | K32: 68.8 | L32: 91.1 | M32: 78.8 | N32: 80.4 | O32: 83.8 | P32: 85.7 | Q32: 12032 | R32: 81.3 | S32: 0.2
B33: gpt5.2-high | C33: 93 | D33: 91.3 | E33: 90.4 | F33: 88.5 | G33: 89.3 | H33: 82 | I33: 81.4 | J33: 75.1 | K33: 75.7 | L33: 93.3 | M33: 82.1 | N33: 84.2 | O33: 89.8 | P33: 86 | Q33: 12032 | R33: 86.4 | S33: 0.3
B34: gpt5.5 | C34: 94 | D34: 92.3 | E34: 90.7 | F34: 89 | G34: 90.2 | H34: 84.7 | I34: 84.1 | J34: 80.3 | K34: 78.7 | L34: 95 | M34: 84.4 | N34: 86.6 | O34: 91.3 | P34: 88 | Q34: 12032 | R34: 88.3 | S34: 0.2
B35: llama-3-8b-vllm | C35: 68.6 | D35: 51.8 | E35: 42.8 | F35: 48.8 | G35: 57.6 | H35: 28.2 | I35: 58.9 | J35: 46.2 | K35: 31.2 | L35: 52.3 | M35: 50.4 | N35: 40.5 | O35: 43.8 | P35: 64.8 | Q35: 12032 | R35: 48.3 | S35: 7.3
B36: qwen3-30b-a3b-thinking-2507-vllm | C36: 88.3 | D36: 82 | E36: 82.8 | F36: 83.7 | G36: 84.7 | H36: 58.7 | I36: 75.8 | J36: 65.6 | K36: 56.1 | L36: 90.9 | M36: 74.8 | N36: 71.9 | O36: 84.4 | P36: 78.7 | Q36: 12032 | R36: 77.6 | S36: 5.7

Sheet Final  (v21) 14B 32B
B1: AthenaBench | T1: CyberSOCEval | Y1: CyberMetric | AB1: Total Score (Avg) | AC1: Weighted Avg Total Score
A2: Model | B2: Type | C2: MMLU-Pro (accuracy) | D2: CKT (Accuracy) | E2: ATE (Accuracy) | F2: RCM (Accuracy) | G2: RMS (F1-score) | J2: VSP (Accuracy) | K2: Threat Actor Attribution (Accuracy) | R2: AB Avg I (Acc) | S2: AB Avg II (Comb) | T2: CyberSOCEval (Accuracy) | Y2: 2000 (acc) | Z2: 10000 (acc) | AA2: Avg
D3: CKT: CTI Knowledge Test (MCQ) | E3: ATE: Attack Technique Enumeration | F3: RCM: Root Cause Mapping | G3: RMS: Risk Mitigation Strategy | J3: VSP: Vulnerability Severity Prediction | K3: TAA Classic | N3: TAA Canonical | Q3: Avg (combined) | T3: Malware | V3: Threat Intel | X3: Combined (acc)
G4: f1 | H4: plausible_f1 | I4: combined_f1 | K4: accurate | L4: plausible | M4: combined | N4: accurate | O4: plausible | P4: combined | T4: acc | U4: avg | V4: acc | W4: avg
A5: gemini-3-flash-preview | B5: FRONTIER | D5: 91.5 | E5: 83.2 | F5: 74.5 | G5: 33.9 | H5: 35.7 | I5: 34.9 | J5: 89 | K5: 37 | L5: 86 | M5: 61.5 | N5: 21.1 | O5: 26.3 | P5: 23.7 | Q5: =AVERAGE(M5,P5) -> 42.6 | R5: =AVERAGE(D5,E5,F5,G5,J5,Q5) -> 69.116667 | S5: =AVERAGE(Q5,J5,I5,F5,E5,D5) -> 69.283333 | T5: 29 | U5: 58.9 | V5: 56.3 | W5: 71.8 | X5: =AVERAGE(T5:V5) -> 48.066667 | Y5: 93.9 | Z5: 90.3 | AA5: =AVERAGE(Y5,Z5) -> 92.1 | AB5: =AVERAGE(X5,S5,AA5) -> 69.816667 | AC5: =AVERAGE(D5,E5,F5,G5,J5,Q5,T5,V5,Y5,Z5) -> 68.42
A6: deepseek-ai/DeepSeek-V4-Pro | B6: PT-OS | D6: 88.8 | E6: 74.8 | F6: 74.1 | G6: 33.8 | H6: 36.6 | I6: 35.4 | J6: 83.5 | K6: 36 | L6: 77 | M6: 74.8 | N6: 17.3 | O6: 20.3 | P6: 18.8 | Q6: =AVERAGE(M6,P6) -> 46.8 | R6: =AVERAGE(D6,E6,F6,G6,J6,Q6) -> 66.966667 | S6: =AVERAGE(Q6,J6,I6,F6,E6,D6) -> 67.233333 | T6: 34.6 | U6: 63.2 | V6: 58.9 | W6: 73.8 | X6: =AVERAGE(T6:V6) -> 52.233333 | Y6: 94.2 | Z6: 89.4 | AA6: =AVERAGE(Y6,Z6) -> 91.8 | AB6: =AVERAGE(X6,S6,AA6) -> 70.422222 | AC6: =AVERAGE(D6,E6,F6,G6,J6,Q6,T6,V6,Y6,Z6) -> 67.89
A7: gpt-5.2 (effort=high) | B7: FRONTIER | D7: 91.5 | E7: 74.4 | F7: 72.4 | G7: 35.7 | H7: 35.7 | I7: 35.7 | J7: 85.9 | K7: 49 | L7: 86 | M7: 67.5 | N7: 30.1 | O7: 33.8 | P7: 32 | Q7: =AVERAGE(M7,P7) -> 49.75 | R7: =AVERAGE(D7,E7,F7,G7,J7,Q7) -> 68.275 | S7: =AVERAGE(Q7,J7,I7,F7,E7,D7) -> 68.275 | T7: 28.5 | U7: 56.7 | V7: 55.9 | W7: 71.8 | X7: =AVERAGE(T7:V7) -> 47.033333 | Y7: 94.3 | Z7: 90.3 | AA7: =AVERAGE(Y7,Z7) -> 92.3 | AB7: =AVERAGE(X7,S7,AA7) -> 69.202778 | AC7: =AVERAGE(D7,E7,F7,G7,J7,Q7,T7,V7,Y7,Z7) -> 67.865
A8: asg-ai/athena-cti-sft-qwen25-32b-v21-recal-32b | B8: SFT | C8: 57.4 | D8: 75.5 | E8: 65.8 | F8: 67.1 | G8: 61.1 | H8: 63.6 | I8: 62.5 | J8: 77.8 | K8: 16 | L8: 85 | M8: 50.5 | N8: 2.3 | O8: 4.5 | P8: 3.4 | Q8: =AVERAGE(M8,P8) -> 26.95 | R8: =AVERAGE(D8,E8,F8,G8,J8,Q8) -> 62.375 | S8: =AVERAGE(Q8,J8,I8,F8,E8,D8) -> 62.608333 | T8: 26.4 | U8: 52.5 | V8: 48.9 | W8: 67.3 | X8: =AVERAGE(T8:V8) -> 42.6 | Y8: 92.2 | Z8: 87.4 | AA8: =AVERAGE(Y8,Z8) -> 89.8 | AB8: =AVERAGE(X8,S8,AA8) -> 65.002778 | AC8: =AVERAGE(D8,E8,F8,G8,J8,Q8,T8,V8,Y8,Z8) -> 62.915
A9: deepseek-ai/DeepSeek-v3.2-Exp | B9: PT-OS | D9: 86.6 | E9: 56.4 | F9: 70.4 | G9: 22.7 | H9: 22.7 | I9: 22.7 | J9: 83.7 | K9: 31 | L9: 88 | M9: 59.5 | N9: 7.5 | O9: 9.8 | P9: 8.7 | Q9: =AVERAGE(M9,P9) -> 34.1 | R9: =AVERAGE(D9,E9,F9,G9,J9,Q9) -> 58.983333 | S9: =AVERAGE(Q9,J9,I9,F9,E9,D9) -> 58.983333 | T9: 28.3 | U9: 57.2 | V9: 56.1 | W9: 73.2 | X9: =AVERAGE(T9:V9) -> 47.2 | Y9: 94.1 | Z9: 89.3 | AA9: =AVERAGE(Y9,Z9) -> 91.7 | AB9: =AVERAGE(X9,S9,AA9) -> 65.961111 | AC9: =AVERAGE(D9,E9,F9,G9,J9,Q9,T9,V9,Y9,Z9) -> 62.17
A10: deepseek-ai/DeepSeek-V3.1-Terminus | B10: PT-OS | D10: 85.7 | E10: 57.8 | F10: 69.3 | G10: 21.6 | H10: 22.8 | I10: 22.3 | J10: 82.7 | K10: 32 | L10: 88 | M10: 60 | N10: 7.5 | O10: 10.5 | P10: 9 | Q10: =AVERAGE(M10,P10) -> 34.5 | R10: =AVERAGE(D10,E10,F10,G10,J10,Q10) -> 58.6 | S10: =AVERAGE(Q10,J10,I10,F10,E10,D10) -> 58.716667 | T10: 27.7 | U10: 56.8 | V10: 56.6 | W10: 73.9 | X10: =AVERAGE(T10:V10) -> 47.033333 | Y10: 94 | Z10: 89.3 | AA10: =AVERAGE(Y10,Z10) -> 91.65 | AB10: =AVERAGE(X10,S10,AA10) -> 65.8 | AC10: =AVERAGE(D10,E10,F10,G10,J10,Q10,T10,V10,Y10,Z10) -> 61.92
A11: asg-ai/athena-cti-sft-qwen3-30b-a3b-thinking-2507-v21-cse | B11: SFT | C11: 52.98 | D11: 74.5 | E11: 58.6 | F11: 68.5 | G11: 48.7 | H11: 51 | I11: 50.1 | J11: 85 | K11: 14 | L11: 80 | M11: 47 | N11: 2.3 | O11: 7.5 | P11: 4.9 | Q11: =AVERAGE(M11,P11) -> 25.95 | R11: =AVERAGE(D11,E11,F11,G11,J11,Q11) -> 60.208333 | S11: =AVERAGE(Q11,J11,I11,F11,E11,D11) -> 60.441667 | T11: 22.5 | U11: 53 | V11: 47.9 | W11: 68.1 | X11: =AVERAGE(T11:V11) -> 41.133333 | Y11: 91 | Z11: 86.2 | AA11: =AVERAGE(Y11,Z11) -> 88.6 | AB11: =AVERAGE(X11,S11,AA11) -> 63.391667 | AC11: =AVERAGE(D11,E11,F11,G11,J11,Q11,T11,V11,Y11,Z11) -> 60.885
A12: asg-ai/athena-cti-sft-qwen25-14b-v21-recalibrate | B12: SFT | C12: 50.2 | D12: 70.4 | E12: 61 | F12: 66.9 | G12: 56.4 | H12: 59.2 | I12: 58 | J12: 83.1 | K12: 14 | L12: 86 | M12: 50 | N12: 2.3 | O12: 4.5 | P12: 3.4 | Q12: =AVERAGE(M12,P12) -> 26.7 | R12: =AVERAGE(D12,E12,F12,G12,J12,Q12) -> 60.75 | S12: =AVERAGE(Q12,J12,I12,F12,E12,D12) -> 61.016667 | T12: 23.5 | U12: 47.8 | V12: 35.5 | W12: 59.4 | X12: =AVERAGE(T12:V12) -> 35.6 | Y12: 88.8 | Z12: 84 | AA12: =AVERAGE(Y12,Z12) -> 86.4 | AB12: =AVERAGE(X12,S12,AA12) -> 61.005556 | AC12: =AVERAGE(D12,E12,F12,G12,J12,Q12,T12,V12,Y12,Z12) -> 59.63
A13: asg-ai/athena-cti-sft-qwen3-30b-a3b-thinking-2507-v21-recalibrate | B13: SFT | D13: 63.3 | E13: 52.8 | F13: 63 | G13: 48.9 | H13: 52.4 | I13: 50.9 | J13: 83.6 | K13: 16 | L13: 82 | M13: 49 | N13: 6 | O13: 19.6 | P13: 12.8 | Q13: =AVERAGE(M13,P13) -> 30.9 | R13: =AVERAGE(D13,E13,F13,G13,J13,Q13) -> 57.083333 | S13: =AVERAGE(Q13,J13,I13,F13,E13,D13) -> 57.416667 | T13: 21.5 | U13: 52.3 | V13: 48.4 | W13: 68.5 | X13: =AVERAGE(T13:V13) -> 40.733333 | Y13: 91.2 | Z13: 86.4 | AA13: =AVERAGE(Y13,Z13) -> 88.8 | AB13: =AVERAGE(X13,S13,AA13) -> 62.316667 | AC13: =AVERAGE(D13,E13,F13,G13,J13,Q13,T13,V13,Y13,Z13) -> 59
A14: asg-ai/athena-cti-sft-qwen3-30b-a3b-thinking-2507-v21-core | B14: SFT | D14: 67.4 | E14: 54.4 | F14: 68.9 | G14: 53.7 | H14: 56.2 | I14: 55.2 | J14: 81.4 | K14: 21 | L14: 80 | M14: 50.5 | N14: 6.8 | O14: 17.3 | P14: 12 | Q14: =AVERAGE(M14,P14) -> 31.25 | R14: =AVERAGE(D14,E14,F14,G14,J14,Q14) -> 59.508333 | S14: =AVERAGE(Q14,J14,I14,F14,E14,D14) -> 59.758333 | T14: 10.5 | U14: 45.3 | V14: 42.4 | W14: 64.1 | X14: =AVERAGE(T14:V14) -> 32.733333 | Y14: 91.9 | Z14: 86.9 | AA14: =AVERAGE(Y14,Z14) -> 89.4 | AB14: =AVERAGE(X14,S14,AA14) -> 60.630556 | AC14: =AVERAGE(D14,E14,F14,G14,J14,Q14,T14,V14,Y14,Z14) -> 58.875
A15: asg-ai/athena-cti-sft-qwen3-30b-a3b-thinking-2507-v21-taa | B15: SFT | D15: 66.3 | E15: 56.4 | F15: 68.3 | G15: 48 | H15: 51.4 | I15: 50 | J15: 79.4 | K15: 15 | L15: 79 | M15: 47 | N15: 10.5 | O15: 28.6 | P15: 19.6 | Q15: =AVERAGE(M15,P15) -> 33.3 | R15: =AVERAGE(D15,E15,F15,G15,J15,Q15) -> 58.616667 | S15: =AVERAGE(Q15,J15,I15,F15,E15,D15) -> 58.95 | T15: 12 | U15: 45.5 | V15: 42.9 | W15: 64.7 | X15: =AVERAGE(T15:V15) -> 33.466667 | Y15: 90.9 | Z15: 86.2 | AA15: =AVERAGE(Y15,Z15) -> 88.55 | AB15: =AVERAGE(X15,S15,AA15) -> 60.322222 | AC15: =AVERAGE(D15,E15,F15,G15,J15,Q15,T15,V15,Y15,Z15) -> 58.37
A16: asg-ai/athena-cti-sft-qwen3-30b-a3b-thinking-2507-v21-recal-32b | B16: SFT | D16: 61.1 | E16: 54.8 | F16: 67.3 | G16: 48.3 | H16: 52.2 | I16: 50.6 | J16: 84.2 | K16: 12 | L16: 79 | M16: 45.5 | N16: 14.3 | O16: 54.1 | P16: 34.2 | Q16: =AVERAGE(M16,P16) -> 39.85 | R16: =AVERAGE(D16,E16,F16,G16,J16,Q16) -> 59.258333 | S16: =AVERAGE(Q16,J16,I16,F16,E16,D16) -> 59.641667 | T16: 20.2 | U16: 51.6 | V16: 46.9 | W16: 67.2 | X16: =AVERAGE(T16:V16) -> 39.566667 | Y16: 81.4 | Z16: 77 | AA16: =AVERAGE(Y16,Z16) -> 79.2 | AB16: =AVERAGE(X16,S16,AA16) -> 59.469444 | AC16: =AVERAGE(D16,E16,F16,G16,J16,Q16,T16,V16,Y16,Z16) -> 58.105
A17: gemini-2.5-flash | B17: FRONTIER | D17: 79 | E17: 51.6 | F17: 65.05 | G17: 12.2 | H17: 12.7 | I17: 12.5 | J17: 78.499 | K17: 30 | L17: 87 | M17: 58.5 | N17: 4.5 | O17: 6 | P17: 5.3 | Q17: =AVERAGE(M17,P17) -> 31.9 | R17: =AVERAGE(D17,E17,F17,G17,J17,Q17) -> 53.0415 | S17: =AVERAGE(Q17,J17,I17,F17,E17,D17) -> 53.0915 | T17: 30.3 | U17: 60.2 | V17: 48 | W17: 67.1 | X17: =AVERAGE(T17:V17) -> 46.166667 | Y17: 93.5 | Z17: 88.6 | AA17: =AVERAGE(Y17,Z17) -> 91.05 | AB17: =AVERAGE(X17,S17,AA17) -> 63.436056 | AC17: =AVERAGE(D17,E17,F17,G17,J17,Q17,T17,V17,Y17,Z17) -> 57.8649
A18: Qwen/Qwen3-30B-A3B-Thinking-2507 | B18: INSTRUCT | C18: 77.58 | D18: 78.7 | E18: 27.2 | F18: 61.1 | G18: 5.2 | H18: 5.4 | I18: 5.3 | J18: 81.18 | K18: 21 | L18: 94 | M18: 57.5 | N18: 0.8 | O18: 2.3 | P18: 1.5 | Q18: =AVERAGE(M18,P18) -> 29.5 | R18: =AVERAGE(D18,E18,F18,G18,J18,Q18) -> 47.146667 | S18: =AVERAGE(Q18,J18,I18,F18,E18,D18) -> 47.163333 | T18: 31.6 | U18: 58.2 | V18: 54.5 | W18: 70.8 | X18: =AVERAGE(T18:V18) -> 48.1 | Y18: 92.5 | Z18: 87.8 | AA18: =AVERAGE(Y18,Z18) -> 90.15 | AB18: =AVERAGE(X18,S18,AA18) -> 61.804444 | AC18: =AVERAGE(D18,E18,F18,G18,J18,Q18,T18,V18,Y18,Z18) -> 54.928
A19: asg-ai/athena-cti-sft-foundation-8b-v21-recalibrate | B19: SFT | D19: 53.8 | E19: 60 | F19: 68.4 | G19: 38.8 | H19: 47.1 | I19: 43.5 | J19: 83.6 | K19: 14 | L19: 67 | M19: 40.5 | N19: 15.8 | O19: 39.1 | P19: 27.4 | Q19: =AVERAGE(M19,P19) -> 33.95 | R19: =AVERAGE(D19,E19,F19,G19,J19,Q19) -> 56.425 | S19: =AVERAGE(Q19,J19,I19,F19,E19,D19) -> 57.208333 | T19: 16.1 | U19: 41.7 | V19: 27.9 | W19: 53.5 | X19: =AVERAGE(T19:V19) -> 28.566667 | Y19: 75.3 | Z19: 73.9 | AA19: =AVERAGE(Y19,Z19) -> 74.6 | AB19: =AVERAGE(X19,S19,AA19) -> 53.458333 | AC19: =AVERAGE(D19,E19,F19,G19,J19,Q19,T19,V19,Y19,Z19) -> 53.175
A20: ftdn-ai/Foundation-Sec-8B-Instruct | B20: INSTRUCT | D20: 77.8 | E20: 36.6 | F20: 65 | G20: 26.9 | H20: 28.2 | I20: 27.7 | J20: 65.3 | K20: 26 | L20: 87 | M20: 56.5 | N20: 3.8 | O20: 15 | P20: 9.4 | Q20: =AVERAGE(M20,P20) -> 32.95 | R20: =AVERAGE(D20,E20,F20,G20,J20,Q20) -> 50.758333 | S20: =AVERAGE(Q20,J20,I20,F20,E20,D20) -> 50.891667 | T20: 16.8 | U20: 48.4 | V20: 38.6 | W20: 62 | X20: =AVERAGE(T20:V20) -> 34.6 | Y20: 85.7 | Z20: 81.7 | AA20: =AVERAGE(Y20,Z20) -> 83.7 | AB20: =AVERAGE(X20,S20,AA20) -> 56.397222 | AC20: =AVERAGE(D20,E20,F20,G20,J20,Q20,T20,V20,Y20,Z20) -> 52.735
A21: asg-ai/athena-cti-sft-llama31-8b-v21-recalibrate | B21: SFT | C21: 27.66 | D21: 59.3 | E21: 60.4 | F21: 67.7 | G21: 57.9 | H21: 60 | I21: 59.1 | J21: 75.3 | K21: 7 | L21: 69 | M21: 38 | N21: 8.3 | O21: 21.1 | P21: 14.7 | Q21: =AVERAGE(M21,P21) -> 26.35 | R21: =AVERAGE(D21,E21,F21,G21,J21,Q21) -> 57.825 | S21: =AVERAGE(Q21,J21,I21,F21,E21,D21) -> 58.025 | T21: 11 | U21: 41.9 | V21: 6.3 | W21: 40.2 | X21: =AVERAGE(T21:V21) -> 19.733333 | Y21: 72.5 | Z21: 70.8 | AA21: =AVERAGE(Y21,Z21) -> 71.65 | AB21: =AVERAGE(X21,S21,AA21) -> 49.802778 | AC21: =AVERAGE(D21,E21,F21,G21,J21,Q21,T21,V21,Y21,Z21) -> 50.755
A22: Qwen/Qwen2.5-32B-Instruct | B22: INSTRUCT | C22: 69 | D22: 52.9 | E22: 18.2 | F22: 59.5 | G22: 7.4 | H22: 7.7 | I22: 7.6 | J22: 78.8 | K22: 16 | L22: 80 | M22: 48 | N22: 1 | O22: 3 | P22: 2 | Q22: =AVERAGE(M22,P22) -> 25 | R22: =AVERAGE(D22,E22,F22,G22,J22,Q22) -> 40.3 | S22: =AVERAGE(Q22,J22,I22,F22,E22,D22) -> 40.333333 | T22: 24.1 | U22: 53.8 | V22: 49.9 | W22: 69.1 | X22: =AVERAGE(T22:V22) -> 42.6 | Y22: 92.6 | Z22: 87.7 | AA22: =AVERAGE(Y22,Z22) -> 90.15 | AB22: =AVERAGE(X22,S22,AA22) -> 57.694444 | AC22: =AVERAGE(D22,E22,F22,G22,J22,Q22,T22,V22,Y22,Z22) -> 49.61
A23: mistralai/Mistral-Small-3.2-24B-Instruct-2506 | B23: INSTRUCT | D23: 39.4 | E23: 32.6 | F23: 57.6 | G23: 7.6 | H23: 7.7 | I23: 7.7 | J23: 73.3 | K23: 10 | L23: 40 | M23: 25 | N23: 3 | O23: 13.5 | P23: 8.3 | Q23: =AVERAGE(M23,P23) -> 16.65 | R23: =AVERAGE(D23,E23,F23,G23,J23,Q23) -> 37.858333 | S23: =AVERAGE(Q23,J23,I23,F23,E23,D23) -> 37.875 | T23: 23 | U23: 53.7 | V23: 49.2 | W23: 69.8 | X23: =AVERAGE(T23:V23) -> 41.966667 | Y23: 91.4 | Z23: 87 | AA23: =AVERAGE(Y23,Z23) -> 89.2 | AB23: =AVERAGE(X23,S23,AA23) -> 56.347222 | AC23: =AVERAGE(D23,E23,F23,G23,J23,Q23,T23,V23,Y23,Z23) -> 47.775
A24: Qwen/Qwen3-30B-A3B-Instruct-2507 (thinking) | B24: INSTRUCT | D24: 35.8 | E24: 21.8 | F24: 57.2 | G24: 5.5 | H24: 5.5 | I24: 5.5 | J24: 73.9 | K24: 22 | L24: 96 | M24: 59 | N24: 0 | O24: 2.3 | P24: 1.1 | Q24: =AVERAGE(M24,P24) -> 30.05 | R24: =AVERAGE(D24,E24,F24,G24,J24,Q24) -> 37.375 | S24: =AVERAGE(Q24,J24,I24,F24,E24,D24) -> 37.375 | T24: 20.2 | U24: 52.8 | V24: 49.8 | W24: 69.6 | X24: =AVERAGE(T24:V24) -> 40.933333 | Y24: 92.3 | Z24: 87.9 | AA24: =AVERAGE(Y24,Z24) -> 90.1 | AB24: =AVERAGE(X24,S24,AA24) -> 56.136111 | AC24: =AVERAGE(D24,E24,F24,G24,J24,Q24,T24,V24,Y24,Z24) -> 47.445
A25: Qwen/Qwen2.5-14B-Instruct | B25: INSTRUCT | C25: 64.1 | D25: 36.8 | E25: 16 | F25: 57.1 | G25: 6.2 | H25: 6.2 | I25: 6.2 | J25: 71.8 | K25: 16 | L25: 88 | M25: 52 | N25: 0 | O25: 0.75 | P25: 0.38 | Q25: =AVERAGE(M25,P25) -> 26.19 | R25: =AVERAGE(D25,E25,F25,G25,J25,Q25) -> 35.681667 | S25: =AVERAGE(Q25,J25,I25,F25,E25,D25) -> 35.681667 | T25: 23.3 | U25: 53 | V25: 47.2 | W25: 68.5 | X25: =AVERAGE(T25:V25) -> 41.166667 | Y25: 91 | Z25: 85.9 | AA25: =AVERAGE(Y25,Z25) -> 88.45 | AB25: =AVERAGE(X25,S25,AA25) -> 55.099444 | AC25: =AVERAGE(D25,E25,F25,G25,J25,Q25,T25,V25,Y25,Z25) -> 46.149
A26: meta-llama/Meta-Llama-3.1-8B-Instruct | B26: INSTRUCT | C26: 48.25 | D26: 59.7 | E26: 12 | F26: 42.1 | G26: 7.8 | H26: 8 | I26: 7.9 | J26: 73.6 | K26: 18 | L26: 64 | M26: 41 | N26: 3.8 | O26: 14.3 | P26: 9 | Q26: =AVERAGE(M26,P26) -> 25 | R26: =AVERAGE(D26,E26,F26,G26,J26,Q26) -> 36.7 | S26: =AVERAGE(Q26,J26,I26,F26,E26,D26) -> 36.716667 | T26: 16.1 | U26: 47.9 | V26: 29.1 | W26: 58.3 | X26: =AVERAGE(T26:V26) -> 31.033333 | Y26: 86.2 | Z26: 82.7 | AA26: =AVERAGE(Y26,Z26) -> 84.45 | AB26: =AVERAGE(X26,S26,AA26) -> 50.733333 | AC26: =AVERAGE(D26,E26,F26,G26,J26,Q26,T26,V26,Y26,Z26) -> 43.43
A27: Qwen/Qwen3-30B-A3B-Instruct-2507 (non-thinking) | B27: INSTRUCT | D27: 18.1 | E27: 25.2 | F27: 38.5 | G27: 6.9 | H27: 7 | I27: 7 | J27: 84.6 | K27: 6 | L27: 39 | M27: 22.5 | N27: 0.8 | O27: 24.8 | P27: 12.8 | Q27: =AVERAGE(M27,P27) -> 17.65 | R27: =AVERAGE(D27,E27,F27,G27,J27,Q27) -> 31.825 | S27: =AVERAGE(Q27,J27,I27,F27,E27,D27) -> 31.841667 | T27: 37.5 | U27: 65.4 | V27: 61.2 | W27: 76.6 | X27: =AVERAGE(T27:V27) -> 54.7 | Y27: 20.2 | Z27: 19.7 | AA27: =AVERAGE(Y27,Z27) -> 19.95 | AB27: =AVERAGE(X27,S27,AA27) -> 35.497222 | AC27: =AVERAGE(D27,E27,F27,G27,J27,Q27,T27,V27,Y27,Z27) -> 32.955

Sheet Prod Target (v21)
B1: AthenaBench | R1: CyberSOCEval | W1: CyberMetric | Z1: Total Score (Avg) | AA1: Weighted Avg Total Score
A2: Model | B2: Type | C2: CKT (Accuracy) | D2: ATE (Accuracy) | E2: RCM (Accuracy) | F2: RMS (F1-score) | I2: VSP (Accuracy) | J2: Threat Actor Attribution (Accuracy) | P2: AB Avg I (Acc) | Q2: AB Avg II (Comb) | R2: CyberSOCEval (Accuracy) | W2: 2000 (acc) | X2: 10000 (acc) | Y2: Avg
C3: CKT: CTI Knowledge Test (MCQ) | D3: ATE: Attack Technique Enumeration | E3: RCM: Root Cause Mapping | F3: RMS: Risk Mitigation Strategy | I3: VSP: Vulnerability Severity Prediction | J3: TAA Classic | M3: TAA Canonical | R3: Malware | T3: Threat Intel | V3: Combined (acc)
F4: f1 | G4: plausible_f1 | H4: combined_f1 | J4: accurate | K4: plausible | L4: combined | M4: accurate | N4: plausible | O4: combined | R4: acc | S4: avg | T4: acc | U4: avg
A5: deepseek-ai/DeepSeek-V4-Pro | B5: PT-OS | C5: 88.8 | D5: 74.8 | E5: 74.1 | F5: 33.8 | G5: 36.6 | H5: 35.4 | I5: 83.5 | J5: 36 | K5: 77 | L5: 74.8 | P5: =AVERAGE(C5,D5,E5,F5,I5,J5) -> 65.166667 | Q5: =AVERAGE(L5,I5,H5,E5,D5,C5) -> 71.9 | R5: 34.6 | S5: 63.2 | T5: 58.9 | U5: 73.8 | V5: =AVERAGE(R5:T5) -> 52.233333 | W5: 94.2 | X5: 89.4 | Y5: =AVERAGE(W5,X5) -> 91.8 | Z5: =AVERAGE(V5,Q5,Y5) -> 71.977778 | AA5: =AVERAGE(C5,D5,E5,F5,I5,L5,R5,T5,W5,X5) -> 70.69
A6: gemini-3-flash-preview | B6: FRONTIER | C6: 91.5 | D6: 83.2 | E6: 74.5 | F6: 33.9 | G6: 35.7 | H6: 34.9 | I6: 89 | J6: 37 | K6: 86 | L6: 61.5 | P6: =AVERAGE(C6,D6,E6,F6,I6,J6) -> 68.183333 | Q6: =AVERAGE(L6,I6,H6,E6,D6,C6) -> 72.433333 | R6: 29 | S6: 58.9 | T6: 56.3 | U6: 71.8 | V6: =AVERAGE(R6:T6) -> 48.066667 | W6: 93.9 | X6: 90.3 | Y6: =AVERAGE(W6,X6) -> 92.1 | Z6: =AVERAGE(V6,Q6,Y6) -> 70.866667 | AA6: =AVERAGE(C6,D6,E6,F6,I6,L6,R6,T6,W6,X6) -> 70.31
A7: gpt-5.2-high | B7: FRONTIER | C7: 91.5 | D7: 74.4 | E7: 72.4 | F7: 35.7 | G7: 35.7 | H7: 35.7 | I7: 85.9 | J7: 49 | K7: 86 | L7: 67.5 | P7: =AVERAGE(C7,D7,E7,F7,I7,J7) -> 68.15 | Q7: =AVERAGE(L7,I7,H7,E7,D7,C7) -> 71.233333 | R7: 28.5 | S7: 56.7 | T7: 55.9 | U7: 71.8 | V7: =AVERAGE(R7:T7) -> 47.033333 | W7: 94.3 | X7: 90.3 | Y7: =AVERAGE(W7,X7) -> 92.3 | Z7: =AVERAGE(V7,Q7,Y7) -> 70.188889 | AA7: =AVERAGE(C7,D7,E7,F7,I7,L7,R7,T7,W7,X7) -> 69.64
A8: asg-ai/athena-cti-sft-qwen25-32b-v21-recal-32b | B8: SFT | C8: 75.5 | D8: 65.8 | E8: 67.1 | F8: 61.1 | G8: 63.6 | H8: 62.5 | I8: 77.8 | J8: 16 | K8: 85 | L8: 50.5 | M8: 2.3 | N8: 4.5 | O8: 3.4 | P8: =AVERAGE(C8,D8,E8,F8,I8,J8) -> 60.55 | Q8: =AVERAGE(L8,I8,H8,E8,D8,C8) -> 66.533333 | R8: 26.4 | S8: 52.5 | T8: 48.9 | U8: 67.3 | V8: =AVERAGE(R8:T8) -> 42.6 | W8: 92.2 | X8: 87.4 | Y8: =AVERAGE(W8,X8) -> 89.8 | Z8: =AVERAGE(V8,Q8,Y8) -> 66.311111 | AA8: =AVERAGE(C8,D8,E8,F8,I8,L8,R8,T8,W8,X8) -> 65.27
A9: asg-ai/athena-cti-sft-qwen25-32b-v21-cse | B9: SFT | C9: 72.5 | D9: 63.4 | E9: 67.7 | F9: 62.4 | G9: 64.7 | H9: 63.7 | I9: 78.9 | J9: 18 | K9: 89 | L9: 53.5 | M9: 3 | N9: 3.8 | O9: 3.4 | P9: =AVERAGE(C9,D9,E9,F9,I9,J9) -> 60.483333 | Q9: =AVERAGE(L9,I9,H9,E9,D9,C9) -> 66.616667 | R9: 28.1 | S9: 53.5 | T9: 44.5 | U9: 64.3 | V9: =AVERAGE(R9:T9) -> 42.033333 | W9: 91 | X9: 86.6 | Y9: =AVERAGE(W9,X9) -> 88.8 | Z9: =AVERAGE(V9,Q9,Y9) -> 65.816667 | AA9: =AVERAGE(C9,D9,E9,F9,I9,L9,R9,T9,W9,X9) -> 64.86
